Workbook

Sheet Tourn_Summary
B3: Dodos | C3: Name | D3: Points Played | E3: O Points | F3: D Points | G3: O Rating | H3: D Rating | I3: O Hold Rate | J3: D Break Rate | L3: Dodos | M3: Introduction | N3: G1 | O3: G2 | P3: G3 | Q3: G4 | R3: G5 | S3: G6 | T3: G7 | U3: Count | V3: Total Count
C4: MMP 1 | D4: ='G1'!AF9+'G2'!AF9+'G3'!AF9+'G4'!AF9+'G5'!AF9+'G6'!AF9+'G7'!AF9 -> 0 | E4: ='G1'!AG9+'G2'!AG9+'G3'!AG9+'G4'!AG9+'G5'!AG9+'G6'!AG9+'G7'!AG9 -> 0 | F4: ='G1'!AH9+'G2'!AH9+'G3'!AH9+'G4'!AH9+'G5'!AH9+'G6'!AH9+'G7'!AH9 -> 0 | G4: ='G1'!AI9+'G2'!AI9+'G3'!AI9+'G4'!AI9+'G5'!AI9+'G6'!AI9+'G7'!AI9 -> 0 | H4: ='G1'!AJ9 +'G2'!AJ9+'G3'!AJ9+'G4'!AJ9+'G5'!AJ9+'G6'!AJ9+'G7'!AJ9 -> 0 | I4: =IF(E4=0,, 1-ABS(G4)/E4) | J4: =IF(F4=0,, ABS(H4)/F4) | L4: =C4 -> MMP 1 | O4: =IF($O$32="G2", 'G2'!$D9,"") | P4: =IF($O$32="G3", 'G3'!$D9,"") | Q4: =IF($O$32="G4", 'G4'!$D9,"") | R4: =IF($O$32="G5", 'G5'!$D9,"") | S4: =IF($O$32="G6", 'G6'!$D9,"") | T4: =IF($O$32="G7", 'G7'!$D9,"") | U4: =SUM(N4:T4) -> 0 | V4: ='G1'!$D9+'G2'!$D9+'G3'!$D9+'G4'!$D9+'G5'!$D9+'G6'!$D9+'G7'!$D9 -> 0
C5: MMP 2 | D5: ='G1'!AF10+'G2'!AF10+'G3'!AF10+'G4'!AF10+'G5'!AF10+'G6'!AF10+'G7'!AF10 -> 0 | E5: ='G1'!AG10+'G2'!AG10+'G3'!AG10+'G4'!AG10+'G5'!AG10+'G6'!AG10+'G7'!AG10 -> 0 | F5: ='G1'!AH10+'G2'!AH10+'G3'!AH10+'G4'!AH10+'G5'!AH10+'G6'!AH10+'G7'!AH10 -> 0 | G5: ='G1'!AI10+'G2'!AI10+'G3'!AI10+'G4'!AI10+'G5'!AI10+'G6'!AI10+'G7'!AI10 -> 0 | H5: ='G1'!AJ10 +'G2'!AJ10+'G3'!AJ10+'G4'!AJ10+'G5'!AJ10+'G6'!AJ10+'G7'!AJ10 -> 0 | I5: =IF(E5=0,, 1-ABS(G5)/E5) | J5: =IF(F5=0,, ABS(H5)/F5) | L5: =C5 -> MMP 2 | N5: =IF($O$32="G1", 'G1'!$D10,"") | O5: =IF($O$32="G2", 'G2'!$D10,"") | P5: =IF($O$32="G3", 'G3'!$D10,"") | Q5: =IF($O$32="G4", 'G4'!$D10,"") | R5: =IF($O$32="G5", 'G5'!$D10,"") | S5: =IF($O$32="G6", 'G6'!$D10,"") | T5: =IF($O$32="G7", 'G7'!$D10,"") | U5: =SUM(N5:T5) -> 0 | V5: ='G1'!$D10+'G2'!$D10+'G3'!$D10+'G4'!$D10+'G5'!$D10+'G6'!$D10+'G7'!$D10 -> 0
C6: MMP 3 | D6: ='G1'!AF11+'G2'!AF11+'G3'!AF11+'G4'!AF11+'G5'!AF11+'G6'!AF11+'G7'!AF11 -> 0 | E6: ='G1'!AG11+'G2'!AG11+'G3'!AG11+'G4'!AG11+'G5'!AG11+'G6'!AG11+'G7'!AG11 -> 0 | F6: ='G1'!AH11+'G2'!AH11+'G3'!AH11+'G4'!AH11+'G5'!AH11+'G6'!AH11+'G7'!AH11 -> 0 | G6: ='G1'!AI11+'G2'!AI11+'G3'!AI11+'G4'!AI11+'G5'!AI11+'G6'!AI11+'G7'!AI11 -> 0 | H6: ='G1'!AJ11 +'G2'!AJ11+'G3'!AJ11+'G4'!AJ11+'G5'!AJ11+'G6'!AJ11+'G7'!AJ11 -> 0 | I6: =IF(E6=0,, 1-ABS(G6)/E6) | J6: =IF(F6=0,, ABS(H6)/F6) | L6: =C6 -> MMP 3 | N6: =IF($O$32="G1", 'G1'!$D11,"") | O6: =IF($O$32="G2", 'G2'!$D11,"") | P6: =IF($O$32="G3", 'G3'!$D11,"") | Q6: =IF($O$32="G4", 'G4'!$D11,"") | R6: =IF($O$32="G5", 'G5'!$D11,"") | S6: =IF($O$32="G6", 'G6'!$D11,"") | T6: =IF($O$32="G7", 'G7'!$D11,"") | U6: =SUM(N6:T6) -> 0 | V6: ='G1'!$D11+'G2'!$D11+'G3'!$D11+'G4'!$D11+'G5'!$D11+'G6'!$D11+'G7'!$D11 -> 0
C7: MMP 4 | D7: ='G1'!AF12+'G2'!AF12+'G3'!AF12+'G4'!AF12+'G5'!AF12+'G6'!AF12+'G7'!AF12 -> 0 | E7: ='G1'!AG12+'G2'!AG12+'G3'!AG12+'G4'!AG12+'G5'!AG12+'G6'!AG12+'G7'!AG12 -> 0 | F7: ='G1'!AH12+'G2'!AH12+'G3'!AH12+'G4'!AH12+'G5'!AH12+'G6'!AH12+'G7'!AH12 -> 0 | G7: ='G1'!AI12+'G2'!AI12+'G3'!AI12+'G4'!AI12+'G5'!AI12+'G6'!AI12+'G7'!AI12 -> 0 | H7: ='G1'!AJ12 +'G2'!AJ12+'G3'!AJ12+'G4'!AJ12+'G5'!AJ12+'G6'!AJ12+'G7'!AJ12 -> 0 | I7: =IF(E7=0,, 1-ABS(G7)/E7) | J7: =IF(F7=0,, ABS(H7)/F7) | L7: =C7 -> MMP 4 | N7: =IF($O$32="G1", 'G1'!$D12,"") | O7: =IF($O$32="G2", 'G2'!$D12,"") | P7: =IF($O$32="G3", 'G3'!$D12,"") | Q7: =IF($O$32="G4", 'G4'!$D12,"") | R7: =IF($O$32="G5", 'G5'!$D12,"") | S7: =IF($O$32="G6", 'G6'!$D12,"") | T7: =IF($O$32="G7", 'G7'!$D12,"") | U7: =SUM(N7:T7) -> 0 | V7: ='G1'!$D12+'G2'!$D12+'G3'!$D12+'G4'!$D12+'G5'!$D12+'G6'!$D12+'G7'!$D12 -> 0
C8: MMP 5 | D8: ='G1'!AF13+'G2'!AF13+'G3'!AF13+'G4'!AF13+'G5'!AF13+'G6'!AF13+'G7'!AF13 -> 0 | E8: ='G1'!AG13+'G2'!AG13+'G3'!AG13+'G4'!AG13+'G5'!AG13+'G6'!AG13+'G7'!AG13 -> 0 | F8: ='G1'!AH13+'G2'!AH13+'G3'!AH13+'G4'!AH13+'G5'!AH13+'G6'!AH13+'G7'!AH13 -> 0 | G8: ='G1'!AI13+'G2'!AI13+'G3'!AI13+'G4'!AI13+'G5'!AI13+'G6'!AI13+'G7'!AI13 -> 0 | H8: ='G1'!AJ13 +'G2'!AJ13+'G3'!AJ13+'G4'!AJ13+'G5'!AJ13+'G6'!AJ13+'G7'!AJ13 -> 0 | I8: =IF(E8=0,, 1-ABS(G8)/E8) | J8: =IF(F8=0,, ABS(H8)/F8) | L8: =C8 -> MMP 5 | N8: =IF($O$32="G1", 'G1'!$D13,"") | O8: =IF($O$32="G2", 'G2'!$D13,"") | P8: =IF($O$32="G3", 'G3'!$D13,"") | Q8: =IF($O$32="G4", 'G4'!$D13,"") | R8: =IF($O$32="G5", 'G5'!$D13,"") | S8: =IF($O$32="G6", 'G6'!$D13,"") | T8: =IF($O$32="G7", 'G7'!$D13,"") | U8: =SUM(N8:T8) -> 0 | V8: ='G1'!$D13+'G2'!$D13+'G3'!$D13+'G4'!$D13+'G5'!$D13+'G6'!$D13+'G7'!$D13 -> 0
C9: MMP 6 | D9: ='G1'!AF14+'G2'!AF14+'G3'!AF14+'G4'!AF14+'G5'!AF14+'G6'!AF14+'G7'!AF14 -> 0 | E9: ='G1'!AG14+'G2'!AG14+'G3'!AG14+'G4'!AG14+'G5'!AG14+'G6'!AG14+'G7'!AG14 -> 0 | F9: ='G1'!AH14+'G2'!AH14+'G3'!AH14+'G4'!AH14+'G5'!AH14+'G6'!AH14+'G7'!AH14 -> 0 | G9: ='G1'!AI14+'G2'!AI14+'G3'!AI14+'G4'!AI14+'G5'!AI14+'G6'!AI14+'G7'!AI14 -> 0 | H9: ='G1'!AJ14 +'G2'!AJ14+'G3'!AJ14+'G4'!AJ14+'G5'!AJ14+'G6'!AJ14+'G7'!AJ14 -> 0 | I9: =IF(E9=0,, 1-ABS(G9)/E9) | J9: =IF(F9=0,, ABS(H9)/F9) | L9: =C9 -> MMP 6 | N9: =IF($O$32="G1", 'G1'!$D14,"") | O9: =IF($O$32="G2", 'G2'!$D14,"") | P9: =IF($O$32="G3", 'G3'!$D14,"") | Q9: =IF($O$32="G4", 'G4'!$D14,"") | R9: =IF($O$32="G5", 'G5'!$D14,"") | S9: =IF($O$32="G6", 'G6'!$D14,"") | T9: =IF($O$32="G7", 'G7'!$D14,"") | U9: =SUM(N9:T9) -> 0 | V9: ='G1'!$D14+'G2'!$D14+'G3'!$D14+'G4'!$D14+'G5'!$D14+'G6'!$D14+'G7'!$D14 -> 0
C10: MMP 7 | D10: ='G1'!AF15+'G2'!AF15+'G3'!AF15+'G4'!AF15+'G5'!AF15+'G6'!AF15+'G7'!AF15 -> 0 | E10: ='G1'!AG15+'G2'!AG15+'G3'!AG15+'G4'!AG15+'G5'!AG15+'G6'!AG15+'G7'!AG15 -> 0 | F10: ='G1'!AH15+'G2'!AH15+'G3'!AH15+'G4'!AH15+'G5'!AH15+'G6'!AH15+'G7'!AH15 -> 0 | G10: ='G1'!AI15+'G2'!AI15+'G3'!AI15+'G4'!AI15+'G5'!AI15+'G6'!AI15+'G7'!AI15 -> 0 | H10: ='G1'!AJ15 +'G2'!AJ15+'G3'!AJ15+'G4'!AJ15+'G5'!AJ15+'G6'!AJ15+'G7'!AJ15 -> 0 | I10: =IF(E10=0,, 1-ABS(G10)/E10) | J10: =IF(F10=0,, ABS(H10)/F10) | L10: =C10 -> MMP 7 | N10: =IF($O$32="G1", 'G1'!$D15,"") | O10: =IF($O$32="G2", 'G2'!$D15,"") | P10: =IF($O$32="G3", 'G3'!$D15,"") | Q10: =IF($O$32="G4", 'G4'!$D15,"") | R10: =IF($O$32="G5", 'G5'!$D15,"") | S10: =IF($O$32="G6", 'G6'!$D15,"") | T10: =IF($O$32="G7", 'G7'!$D15,"") | U10: =SUM(N10:T10) -> 0 | V10: ='G1'!$D15+'G2'!$D15+'G3'!$D15+'G4'!$D15+'G5'!$D15+'G6'!$D15+'G7'!$D15 -> 0
C11: MMP 8 | D11: ='G1'!AF16+'G2'!AF16+'G3'!AF16+'G4'!AF16+'G5'!AF16+'G6'!AF16+'G7'!AF16 -> 0 | E11: ='G1'!AG16+'G2'!AG16+'G3'!AG16+'G4'!AG16+'G5'!AG16+'G6'!AG16+'G7'!AG16 -> 0 | F11: ='G1'!AH16+'G2'!AH16+'G3'!AH16+'G4'!AH16+'G5'!AH16+'G6'!AH16+'G7'!AH16 -> 0 | G11: ='G1'!AI16+'G2'!AI16+'G3'!AI16+'G4'!AI16+'G5'!AI16+'G6'!AI16+'G7'!AI16 -> 0 | H11: ='G1'!AJ16 +'G2'!AJ16+'G3'!AJ16+'G4'!AJ16+'G5'!AJ16+'G6'!AJ16+'G7'!AJ16 -> 0 | I11: =IF(E11=0,, 1-ABS(G11)/E11) | J11: =IF(F11=0,, ABS(H11)/F11) | L11: =C11 -> MMP 8 | N11: =IF($O$32="G1", 'G1'!$D16,"") | O11: =IF($O$32="G2", 'G2'!$D16,"") | P11: =IF($O$32="G3", 'G3'!$D16,"") | Q11: =IF($O$32="G4", 'G4'!$D16,"") | R11: =IF($O$32="G5", 'G5'!$D16,"") | S11: =IF($O$32="G6", 'G6'!$D16,"") | T11: =IF($O$32="G7", 'G7'!$D16,"") | U11: =SUM(N11:T11) -> 0 | V11: ='G1'!$D16+'G2'!$D16+'G3'!$D16+'G4'!$D16+'G5'!$D16+'G6'!$D16+'G7'!$D16 -> 0
C12: MMP 9 | D12: ='G1'!AF17+'G2'!AF17+'G3'!AF17+'G4'!AF17+'G5'!AF17+'G6'!AF17+'G7'!AF17 -> 0 | E12: ='G1'!AG17+'G2'!AG17+'G3'!AG17+'G4'!AG17+'G5'!AG17+'G6'!AG17+'G7'!AG17 -> 0 | F12: ='G1'!AH17+'G2'!AH17+'G3'!AH17+'G4'!AH17+'G5'!AH17+'G6'!AH17+'G7'!AH17 -> 0 | G12: ='G1'!AI17+'G2'!AI17+'G3'!AI17+'G4'!AI17+'G5'!AI17+'G6'!AI17+'G7'!AI17 -> 0 | H12: ='G1'!AJ17 +'G2'!AJ17+'G3'!AJ17+'G4'!AJ17+'G5'!AJ17+'G6'!AJ17+'G7'!AJ17 -> 0 | I12: =IF(E12=0,, 1-ABS(G12)/E12) | J12: =IF(F12=0,, ABS(H12)/F12) | L12: =C12 -> MMP 9 | N12: =IF($O$32="G1", 'G1'!$D17,"") | O12: =IF($O$32="G2", 'G2'!$D17,"") | P12: =IF($O$32="G3", 'G3'!$D17,"") | Q12: =IF($O$32="G4", 'G4'!$D17,"") | R12: =IF($O$32="G5", 'G5'!$D17,"") | S12: =IF($O$32="G6", 'G6'!$D17,"") | T12: =IF($O$32="G7", 'G7'!$D17,"") | U12: =SUM(N12:T12) -> 0 | V12: ='G1'!$D17+'G2'!$D17+'G3'!$D17+'G4'!$D17+'G5'!$D17+'G6'!$D17+'G7'!$D17 -> 0
C13: MMP 10 | D13: ='G1'!AF18+'G2'!AF18+'G3'!AF18+'G4'!AF18+'G5'!AF18+'G6'!AF18+'G7'!AF18 -> 0 | E13: ='G1'!AG18+'G2'!AG18+'G3'!AG18+'G4'!AG18+'G5'!AG18+'G6'!AG18+'G7'!AG18 -> 0 | F13: ='G1'!AH18+'G2'!AH18+'G3'!AH18+'G4'!AH18+'G5'!AH18+'G6'!AH18+'G7'!AH18 -> 0 | G13: ='G1'!AI18+'G2'!AI18+'G3'!AI18+'G4'!AI18+'G5'!AI18+'G6'!AI18+'G7'!AI18 -> 0 | H13: ='G1'!AJ18 +'G2'!AJ18+'G3'!AJ18+'G4'!AJ18+'G5'!AJ18+'G6'!AJ18+'G7'!AJ18 -> 0 | I13: =IF(E13=0,, 1-ABS(G13)/E13) | J13: =IF(F13=0,, ABS(H13)/F13) | L13: =C13 -> MMP 10 | N13: =IF($O$32="G1", 'G1'!$D18,"") | O13: =IF($O$32="G2", 'G2'!$D18,"") | P13: =IF($O$32="G3", 'G3'!$D18,"") | Q13: =IF($O$32="G4", 'G4'!$D18,"") | R13: =IF($O$32="G5", 'G5'!$D18,"") | S13: =IF($O$32="G6", 'G6'!$D18,"") | T13: =IF($O$32="G7", 'G7'!$D18,"") | U13: =SUM(N13:T13) -> 0 | V13: ='G1'!$D18+'G2'!$D18+'G3'!$D18+'G4'!$D18+'G5'!$D18+'G6'!$D18+'G7'!$D18 -> 0
C14: MMP 11 | D14: ='G1'!AF19+'G2'!AF19+'G3'!AF19+'G4'!AF19+'G5'!AF19+'G6'!AF19+'G7'!AF19 -> 0 | E14: ='G1'!AG19+'G2'!AG19+'G3'!AG19+'G4'!AG19+'G5'!AG19+'G6'!AG19+'G7'!AG19 -> 0 | F14: ='G1'!AH19+'G2'!AH19+'G3'!AH19+'G4'!AH19+'G5'!AH19+'G6'!AH19+'G7'!AH19 -> 0 | G14: ='G1'!AI19+'G2'!AI19+'G3'!AI19+'G4'!AI19+'G5'!AI19+'G6'!AI19+'G7'!AI19 -> 0 | H14: ='G1'!AJ19 +'G2'!AJ19+'G3'!AJ19+'G4'!AJ19+'G5'!AJ19+'G6'!AJ19+'G7'!AJ19 -> 0 | I14: =IF(E14=0,, 1-ABS(G14)/E14) | J14: =IF(F14=0,, ABS(H14)/F14) | L14: =C14 -> MMP 11 | N14: =IF($O$32="G1", 'G1'!$D19,"") | O14: =IF($O$32="G2", 'G2'!$D19,"") | P14: =IF($O$32="G3", 'G3'!$D19,"") | Q14: =IF($O$32="G4", 'G4'!$D19,"") | R14: =IF($O$32="G5", 'G5'!$D19,"") | S14: =IF($O$32="G6", 'G6'!$D19,"") | T14: =IF($O$32="G7", 'G7'!$D19,"") | U14: =SUM(N14:T14) -> 0 | V14: ='G1'!$D19+'G2'!$D19+'G3'!$D19+'G4'!$D19+'G5'!$D19+'G6'!$D19+'G7'!$D19 -> 0
C15: MMP 12 | D15: ='G1'!AF20+'G2'!AF20+'G3'!AF20+'G4'!AF20+'G5'!AF20+'G6'!AF20+'G7'!AF20 -> 0 | E15: ='G1'!AG20+'G2'!AG20+'G3'!AG20+'G4'!AG20+'G5'!AG20+'G6'!AG20+'G7'!AG20 -> 0 | F15: ='G1'!AH20+'G2'!AH20+'G3'!AH20+'G4'!AH20+'G5'!AH20+'G6'!AH20+'G7'!AH20 -> 0 | G15: ='G1'!AI20+'G2'!AI20+'G3'!AI20+'G4'!AI20+'G5'!AI20+'G6'!AI20+'G7'!AI20 -> 0 | H15: ='G1'!AJ20 +'G2'!AJ20+'G3'!AJ20+'G4'!AJ20+'G5'!AJ20+'G6'!AJ20+'G7'!AJ20 -> 0 | I15: =IF(E15=0,, 1-ABS(G15)/E15) | J15: =IF(F15=0,, ABS(H15)/F15) | L15: =C15 -> MMP 12 | N15: =IF($O$32="G1", 'G1'!$D20,"") | O15: =IF($O$32="G2", 'G2'!$D20,"") | P15: =IF($O$32="G3", 'G3'!$D20,"") | Q15: =IF($O$32="G4", 'G4'!$D20,"") | R15: =IF($O$32="G5", 'G5'!$D20,"") | S15: =IF($O$32="G6", 'G6'!$D20,"") | T15: =IF($O$32="G7", 'G7'!$D20,"") | U15: =SUM(N15:T15) -> 0 | V15: ='G1'!$D20+'G2'!$D20+'G3'!$D20+'G4'!$D20+'G5'!$D20+'G6'!$D20+'G7'!$D20 -> 0
C16: MMP 13 | D16: ='G1'!AF21+'G2'!AF21+'G3'!AF21+'G4'!AF21+'G5'!AF21+'G6'!AF21+'G7'!AF21 -> 0 | E16: ='G1'!AG21+'G2'!AG21+'G3'!AG21+'G4'!AG21+'G5'!AG21+'G6'!AG21+'G7'!AG21 -> 0 | F16: ='G1'!AH21+'G2'!AH21+'G3'!AH21+'G4'!AH21+'G5'!AH21+'G6'!AH21+'G7'!AH21 -> 0 | G16: ='G1'!AI21+'G2'!AI21+'G3'!AI21+'G4'!AI21+'G5'!AI21+'G6'!AI21+'G7'!AI21 -> 0 | H16: ='G1'!AJ21 +'G2'!AJ21+'G3'!AJ21+'G4'!AJ21+'G5'!AJ21+'G6'!AJ21+'G7'!AJ21 -> 0 | I16: =IF(E16=0,, 1-ABS(G16)/E16) | J16: =IF(F16=0,, ABS(H16)/F16) | L16: =C16 -> MMP 13 | N16: =IF($O$32="G1", 'G1'!$D21,"") | O16: =IF($O$32="G2", 'G2'!$D21,"") | P16: =IF($O$32="G3", 'G3'!$D21,"") | Q16: =IF($O$32="G4", 'G4'!$D21,"") | R16: =IF($O$32="G5", 'G5'!$D21,"") | S16: =IF($O$32="G6", 'G6'!$D21,"") | T16: =IF($O$32="G7", 'G7'!$D21,"") | U16: =SUM(N16:T16) -> 0 | V16: ='G1'!$D21+'G2'!$D21+'G3'!$D21+'G4'!$D21+'G5'!$D21+'G6'!$D21+'G7'!$D21 -> 0
B17: Penguins | L17: Penguins
C18: FMP 1 | D18: ='G1'!AF25+'G2'!AF25+'G3'!AF25+'G4'!AF25+'G5'!AF25+'G6'!AF25+'G7'!AF25 -> 0 | E18: ='G1'!AG25+'G2'!AG25+'G3'!AG25+'G4'!AG25+'G5'!AG25+'G6'!AG25+'G7'!AG25 -> 0 | F18: ='G1'!AH25+'G2'!AH25+'G3'!AH25+'G4'!AH25+'G5'!AH25+'G6'!AH25+'G7'!AH25 -> 0 | G18: ='G1'!AI25+'G2'!AI25+'G3'!AI25+'G4'!AI25+'G5'!AI25+'G6'!AI25+'G7'!AI25 -> 0 | H18: ='G1'!AJ25+'G2'!AJ25+'G3'!AJ25+'G4'!AJ25+'G5'!AJ25+'G6'!AJ25+'G7'!AJ25 -> 0 | I18: =IF(E18=0,, 1-ABS(G18)/E18) | J18: =IF(F18=0,, ABS(H18)/F18) | L18: =C18 -> FMP 1 | N18: =IF($O$32 ="G1", 'G1'!$D25,"") | O18: =IF($O$32 ="G2", 'G2'!$D25,"") | P18: =IF($O$32 ="G3", 'G3'!$D25,"") | Q18: =IF($O$32 ="G4", 'G4'!$D25,"") | R18: =IF($O$32 ="G5", 'G5'!$D25,"") | S18: =IF($O$32 ="G6", 'G6'!$D25,"") | T18: =IF($O$32 ="G7", 'G7'!$D25,"") | U18: =SUM(N18:T18) -> 0 | V18: ='G1'!$D25+'G2'!$D25+'G3'!$D25+'G4'!$D25+'G5'!$D25+'G6'!$D25+'G7'!$D25 -> 0
C19: FMP 2 | D19: ='G1'!AF26+'G2'!AF26+'G3'!AF26+'G4'!AF26+'G5'!AF26+'G6'!AF26+'G7'!AF26 -> 0 | E19: ='G1'!AG26+'G2'!AG26+'G3'!AG26+'G4'!AG26+'G5'!AG26+'G6'!AG26+'G7'!AG26 -> 0 | F19: ='G1'!AH26+'G2'!AH26+'G3'!AH26+'G4'!AH26+'G5'!AH26+'G6'!AH26+'G7'!AH26 -> 0 | G19: ='G1'!AI26+'G2'!AI26+'G3'!AI26+'G4'!AI26+'G5'!AI26+'G6'!AI26+'G7'!AI26 -> 0 | H19: ='G1'!AJ26+'G2'!AJ26+'G3'!AJ26+'G4'!AJ26+'G5'!AJ26+'G6'!AJ26+'G7'!AJ26 -> 0 | I19: =IF(E19=0,, 1-ABS(G19)/E19) | J19: =IF(F19=0,, ABS(H19)/F19) | L19: =C19 -> FMP 2 | N19: =IF($O$32 ="G1", 'G1'!$D26,"") | O19: =IF($O$32 ="G2", 'G2'!$D26,"") | P19: =IF($O$32 ="G3", 'G3'!$D26,"") | Q19: =IF($O$32 ="G4", 'G4'!$D26,"") | R19: =IF($O$32 ="G5", 'G5'!$D26,"") | S19: =IF($O$32 ="G6", 'G6'!$D26,"") | T19: =IF($O$32 ="G7", 'G7'!$D26,"") | U19: =SUM(N19:T19) -> 0 | V19: ='G1'!$D26+'G2'!$D26+'G3'!$D26+'G4'!$D26+'G5'!$D26+'G6'!$D26+'G7'!$D26 -> 0
C20: FMP 3 | D20: ='G1'!AF27+'G2'!AF27+'G3'!AF27+'G4'!AF27+'G5'!AF27+'G6'!AF27+'G7'!AF27 -> 0 | E20: ='G1'!AG27+'G2'!AG27+'G3'!AG27+'G4'!AG27+'G5'!AG27+'G6'!AG27+'G7'!AG27 -> 0 | F20: ='G1'!AH27+'G2'!AH27+'G3'!AH27+'G4'!AH27+'G5'!AH27+'G6'!AH27+'G7'!AH27 -> 0 | G20: ='G1'!AI27+'G2'!AI27+'G3'!AI27+'G4'!AI27+'G5'!AI27+'G6'!AI27+'G7'!AI27 -> 0 | H20: ='G1'!AJ27+'G2'!AJ27+'G3'!AJ27+'G4'!AJ27+'G5'!AJ27+'G6'!AJ27+'G7'!AJ27 -> 0 | I20: =IF(E20=0,, 1-ABS(G20)/E20) | J20: =IF(F20=0,, ABS(H20)/F20) | L20: =C20 -> FMP 3 | N20: =IF($O$32 ="G1", 'G1'!$D27,"") | O20: =IF($O$32 ="G2", 'G2'!$D27,"") | P20: =IF($O$32 ="G3", 'G3'!$D27,"") | Q20: =IF($O$32 ="G4", 'G4'!$D27,"") | R20: =IF($O$32 ="G5", 'G5'!$D27,"") | S20: =IF($O$32 ="G6", 'G6'!$D27,"") | T20: =IF($O$32 ="G7", 'G7'!$D27,"") | U20: =SUM(N20:T20) -> 0 | V20: ='G1'!$D27+'G2'!$D27+'G3'!$D27+'G4'!$D27+'G5'!$D27+'G6'!$D27+'G7'!$D27 -> 0
C21: FMP 4 | D21: ='G1'!AF28+'G2'!AF28+'G3'!AF28+'G4'!AF28+'G5'!AF28+'G6'!AF28+'G7'!AF28 -> 0 | E21: ='G1'!AG28+'G2'!AG28+'G3'!AG28+'G4'!AG28+'G5'!AG28+'G6'!AG28+'G7'!AG28 -> 0 | F21: ='G1'!AH28+'G2'!AH28+'G3'!AH28+'G4'!AH28+'G5'!AH28+'G6'!AH28+'G7'!AH28 -> 0 | G21: ='G1'!AI28+'G2'!AI28+'G3'!AI28+'G4'!AI28+'G5'!AI28+'G6'!AI28+'G7'!AI28 -> 0 | H21: ='G1'!AJ28+'G2'!AJ28+'G3'!AJ28+'G4'!AJ28+'G5'!AJ28+'G6'!AJ28+'G7'!AJ28 -> 0 | I21: =IF(E21=0,, 1-ABS(G21)/E21) | J21: =IF(F21=0,, ABS(H21)/F21) | L21: =C21 -> FMP 4 | N21: =IF($O$32 ="G1", 'G1'!$D28,"") | O21: =IF($O$32 ="G2", 'G2'!$D28,"") | P21: =IF($O$32 ="G3", 'G3'!$D28,"") | Q21: =IF($O$32 ="G4", 'G4'!$D28,"") | R21: =IF($O$32 ="G5", 'G5'!$D28,"") | S21: =IF($O$32 ="G6", 'G6'!$D28,"") | T21: =IF($O$32 ="G7", 'G7'!$D28,"") | U21: =SUM(N21:T21) -> 0 | V21: ='G1'!$D28+'G2'!$D28+'G3'!$D28+'G4'!$D28+'G5'!$D28+'G6'!$D28+'G7'!$D28 -> 0
C22: FMP 5 | D22: ='G1'!AF29+'G2'!AF29+'G3'!AF29+'G4'!AF29+'G5'!AF29+'G6'!AF29+'G7'!AF29 -> 0 | E22: ='G1'!AG29+'G2'!AG29+'G3'!AG29+'G4'!AG29+'G5'!AG29+'G6'!AG29+'G7'!AG29 -> 0 | F22: ='G1'!AH29+'G2'!AH29+'G3'!AH29+'G4'!AH29+'G5'!AH29+'G6'!AH29+'G7'!AH29 -> 0 | G22: ='G1'!AI29+'G2'!AI29+'G3'!AI29+'G4'!AI29+'G5'!AI29+'G6'!AI29+'G7'!AI29 -> 0 | H22: ='G1'!AJ29+'G2'!AJ29+'G3'!AJ29+'G4'!AJ29+'G5'!AJ29+'G6'!AJ29+'G7'!AJ29 -> 0 | I22: =IF(E22=0,, 1-ABS(G22)/E22) | J22: =IF(F22=0,, ABS(H22)/F22) | L22: =C22 -> FMP 5 | N22: =IF($O$32 ="G1", 'G1'!$D29,"") | O22: =IF($O$32 ="G2", 'G2'!$D29,"") | P22: =IF($O$32 ="G3", 'G3'!$D29,"") | Q22: =IF($O$32 ="G4", 'G4'!$D29,"") | R22: =IF($O$32 ="G5", 'G5'!$D29,"") | S22: =IF($O$32 ="G6", 'G6'!$D29,"") | T22: =IF($O$32 ="G7", 'G7'!$D29,"") | U22: =SUM(N22:T22) -> 0 | V22: ='G1'!$D29+'G2'!$D29+'G3'!$D29+'G4'!$D29+'G5'!$D29+'G6'!$D29+'G7'!$D29 -> 0
C23: FMP 6 | D23: ='G1'!AF30+'G2'!AF30+'G3'!AF30+'G4'!AF30+'G5'!AF30+'G6'!AF30+'G7'!AF30 -> 0 | E23: ='G1'!AG30+'G2'!AG30+'G3'!AG30+'G4'!AG30+'G5'!AG30+'G6'!AG30+'G7'!AG30 -> 0 | F23: ='G1'!AH30+'G2'!AH30+'G3'!AH30+'G4'!AH30+'G5'!AH30+'G6'!AH30+'G7'!AH30 -> 0 | G23: ='G1'!AI30+'G2'!AI30+'G3'!AI30+'G4'!AI30+'G5'!AI30+'G6'!AI30+'G7'!AI30 -> 0 | H23: ='G1'!AJ30+'G2'!AJ30+'G3'!AJ30+'G4'!AJ30+'G5'!AJ30+'G6'!AJ30+'G7'!AJ30 -> 0 | I23: =IF(E23=0,, 1-ABS(G23)/E23) | J23: =IF(F23=0,, ABS(H23)/F23) | L23: =C23 -> FMP 6 | N23: =IF($O$32 ="G1", 'G1'!$D30,"") | O23: =IF($O$32 ="G2", 'G2'!$D30,"") | P23: =IF($O$32 ="G3", 'G3'!$D30,"") | Q23: =IF($O$32 ="G4", 'G4'!$D30,"") | R23: =IF($O$32 ="G5", 'G5'!$D30,"") | S23: =IF($O$32 ="G6", 'G6'!$D30,"") | T23: =IF($O$32 ="G7", 'G7'!$D30,"") | U23: =SUM(N23:T23) -> 0 | V23: ='G1'!$D30+'G2'!$D30+'G3'!$D30+'G4'!$D30+'G5'!$D30+'G6'!$D30+'G7'!$D30 -> 0
C24: FMP 7 | D24: ='G1'!AF31+'G2'!AF31+'G3'!AF31+'G4'!AF31+'G5'!AF31+'G6'!AF31+'G7'!AF31 -> 0 | E24: ='G1'!AG31+'G2'!AG31+'G3'!AG31+'G4'!AG31+'G5'!AG31+'G6'!AG31+'G7'!AG31 -> 0 | F24: ='G1'!AH31+'G2'!AH31+'G3'!AH31+'G4'!AH31+'G5'!AH31+'G6'!AH31+'G7'!AH31 -> 0 | G24: ='G1'!AI31+'G2'!AI31+'G3'!AI31+'G4'!AI31+'G5'!AI31+'G6'!AI31+'G7'!AI31 -> 0 | H24: ='G1'!AJ31+'G2'!AJ31+'G3'!AJ31+'G4'!AJ31+'G5'!AJ31+'G6'!AJ31+'G7'!AJ31 -> 0 | I24: =IF(E24=0,, 1-ABS(G24)/E24) | J24: =IF(F24=0,, ABS(H24)/F24) | L24: =C24 -> FMP 7 | N24: =IF($O$32 ="G1", 'G1'!$D31,"") | O24: =IF($O$32 ="G2", 'G2'!$D31,"") | P24: =IF($O$32 ="G3", 'G3'!$D31,"") | Q24: =IF($O$32 ="G4", 'G4'!$D31,"") | R24: =IF($O$32 ="G5", 'G5'!$D31,"") | S24: =IF($O$32 ="G6", 'G6'!$D31,"") | T24: =IF($O$32 ="G7", 'G7'!$D31,"") | U24: =SUM(N24:T24) -> 0 | V24: ='G1'!$D31+'G2'!$D31+'G3'!$D31+'G4'!$D31+'G5'!$D31+'G6'!$D31+'G7'!$D31 -> 0
C25: FMP 8 | D25: ='G1'!AF32+'G2'!AF32+'G3'!AF32+'G4'!AF32+'G5'!AF32+'G6'!AF32+'G7'!AF32 -> 0 | E25: ='G1'!AG32+'G2'!AG32+'G3'!AG32+'G4'!AG32+'G5'!AG32+'G6'!AG32+'G7'!AG32 -> 0 | F25: ='G1'!AH32+'G2'!AH32+'G3'!AH32+'G4'!AH32+'G5'!AH32+'G6'!AH32+'G7'!AH32 -> 0 | G25: ='G1'!AI32+'G2'!AI32+'G3'!AI32+'G4'!AI32+'G5'!AI32+'G6'!AI32+'G7'!AI32 -> 0 | H25: ='G1'!AJ32+'G2'!AJ32+'G3'!AJ32+'G4'!AJ32+'G5'!AJ32+'G6'!AJ32+'G7'!AJ32 -> 0 | I25: =IF(E25=0,, 1-ABS(G25)/E25) | J25: =IF(F25=0,, ABS(H25)/F25) | L25: =C25 -> FMP 8 | N25: =IF($O$32 ="G1", 'G1'!$D32,"") | O25: =IF($O$32 ="G2", 'G2'!$D32,"") | P25: =IF($O$32 ="G3", 'G3'!$D32,"") | Q25: =IF($O$32 ="G4", 'G4'!$D32,"") | R25: =IF($O$32 ="G5", 'G5'!$D32,"") | S25: =IF($O$32 ="G6", 'G6'!$D32,"") | T25: =IF($O$32 ="G7", 'G7'!$D32,"") | U25: =SUM(N25:T25) -> 0 | V25: ='G1'!$D32+'G2'!$D32+'G3'!$D32+'G4'!$D32+'G5'!$D32+'G6'!$D32+'G7'!$D32 -> 0
C26: FMP 9 | D26: ='G1'!AF33+'G2'!AF33+'G3'!AF33+'G4'!AF33+'G5'!AF33+'G6'!AF33+'G7'!AF33 -> 0 | E26: ='G1'!AG33+'G2'!AG33+'G3'!AG33+'G4'!AG33+'G5'!AG33+'G6'!AG33+'G7'!AG33 -> 0 | F26: ='G1'!AH33+'G2'!AH33+'G3'!AH33+'G4'!AH33+'G5'!AH33+'G6'!AH33+'G7'!AH33 -> 0 | G26: ='G1'!AI33+'G2'!AI33+'G3'!AI33+'G4'!AI33+'G5'!AI33+'G6'!AI33+'G7'!AI33 -> 0 | H26: ='G1'!AJ33+'G2'!AJ33+'G3'!AJ33+'G4'!AJ33+'G5'!AJ33+'G6'!AJ33+'G7'!AJ33 -> 0 | I26: =IF(E26=0,, 1-ABS(G26)/E26) | J26: =IF(F26=0,, ABS(H26)/F26) | L26: =C26 -> FMP 9 | N26: =IF($O$32 ="G1", 'G1'!$D33,"") | O26: =IF($O$32 ="G2", 'G2'!$D33,"") | P26: =IF($O$32 ="G3", 'G3'!$D33,"") | Q26: =IF($O$32 ="G4", 'G4'!$D33,"") | R26: =IF($O$32 ="G5", 'G5'!$D33,"") | S26: =IF($O$32 ="G6", 'G6'!$D33,"") | T26: =IF($O$32 ="G7", 'G7'!$D33,"") | U26: =SUM(N26:T26) -> 0 | V26: ='G1'!$D33+'G2'!$D33+'G3'!$D33+'G4'!$D33+'G5'!$D33+'G6'!$D33+'G7'!$D33 -> 0
C27: FMP 10 | D27: ='G1'!AF34+'G2'!AF34+'G3'!AF34+'G4'!AF34+'G5'!AF34+'G6'!AF34+'G7'!AF34 -> 0 | E27: ='G1'!AG34+'G2'!AG34+'G3'!AG34+'G4'!AG34+'G5'!AG34+'G6'!AG34+'G7'!AG34 -> 0 | F27: ='G1'!AH34+'G2'!AH34+'G3'!AH34+'G4'!AH34+'G5'!AH34+'G6'!AH34+'G7'!AH34 -> 0 | G27: ='G1'!AI34+'G2'!AI34+'G3'!AI34+'G4'!AI34+'G5'!AI34+'G6'!AI34+'G7'!AI34 -> 0 | H27: ='G1'!AJ34+'G2'!AJ34+'G3'!AJ34+'G4'!AJ34+'G5'!AJ34+'G6'!AJ34+'G7'!AJ34 -> 0 | I27: =IF(E27=0,, 1-ABS(G27)/E27) | J27: =IF(F27=0,, ABS(H27)/F27) | L27: =C27 -> FMP 10 | N27: =IF($O$32 ="G1", 'G1'!$D34,"") | O27: =IF($O$32 ="G2", 'G2'!$D34,"") | P27: =IF($O$32 ="G3", 'G3'!$D34,"") | Q27: =IF($O$32 ="G4", 'G4'!$D34,"") | R27: =IF($O$32 ="G5", 'G5'!$D34,"") | S27: =IF($O$32 ="G6", 'G6'!$D34,"") | T27: =IF($O$32 ="G7", 'G7'!$D34,"") | U27: =SUM(N27:T27) -> 0 | V27: ='G1'!$D34+'G2'!$D34+'G3'!$D34+'G4'!$D34+'G5'!$D34+'G6'!$D34+'G7'!$D34 -> 0
C28: FMP 11 | D28: ='G1'!AF35+'G2'!AF35+'G3'!AF35+'G4'!AF35+'G5'!AF35+'G6'!AF35+'G7'!AF35 -> 0 | E28: ='G1'!AG35+'G2'!AG35+'G3'!AG35+'G4'!AG35+'G5'!AG35+'G6'!AG35+'G7'!AG35 -> 0 | F28: ='G1'!AH35+'G2'!AH35+'G3'!AH35+'G4'!AH35+'G5'!AH35+'G6'!AH35+'G7'!AH35 -> 0 | G28: ='G1'!AI35+'G2'!AI35+'G3'!AI35+'G4'!AI35+'G5'!AI35+'G6'!AI35+'G7'!AI35 -> 0 | H28: ='G1'!AJ35+'G2'!AJ35+'G3'!AJ35+'G4'!AJ35+'G5'!AJ35+'G6'!AJ35+'G7'!AJ35 -> 0 | I28: =IF(E28=0,, 1-ABS(G28)/E28) | J28: =IF(F28=0,, ABS(H28)/F28) | L28: =C28 -> FMP 11 | N28: =IF($O$32 ="G1", 'G1'!$D35,"") | O28: =IF($O$32 ="G2", 'G2'!$D35,"") | P28: =IF($O$32 ="G3", 'G3'!$D35,"") | Q28: =IF($O$32 ="G4", 'G4'!$D35,"") | R28: =IF($O$32 ="G5", 'G5'!$D35,"") | S28: =IF($O$32 ="G6", 'G6'!$D35,"") | T28: =IF($O$32 ="G7", 'G7'!$D35,"") | U28: =SUM(N28:T28) -> 0 | V28: ='G1'!$D35+'G2'!$D35+'G3'!$D35+'G4'!$D35+'G5'!$D35+'G6'!$D35+'G7'!$D35 -> 0
C29: FMP 12 | D29: ='G1'!AF36+'G2'!AF36+'G3'!AF36+'G4'!AF36+'G5'!AF36+'G6'!AF36+'G7'!AF36 -> 0 | E29: ='G1'!AG36+'G2'!AG36+'G3'!AG36+'G4'!AG36+'G5'!AG36+'G6'!AG36+'G7'!AG36 -> 0 | F29: ='G1'!AH36+'G2'!AH36+'G3'!AH36+'G4'!AH36+'G5'!AH36+'G6'!AH36+'G7'!AH36 -> 0 | G29: ='G1'!AI36+'G2'!AI36+'G3'!AI36+'G4'!AI36+'G5'!AI36+'G6'!AI36+'G7'!AI36 -> 0 | H29: ='G1'!AJ36+'G2'!AJ36+'G3'!AJ36+'G4'!AJ36+'G5'!AJ36+'G6'!AJ36+'G7'!AJ36 -> 0 | I29: =IF(E29=0,, 1-ABS(G29)/E29) | J29: =IF(F29=0,, ABS(H29)/F29) | L29: =C29 -> FMP 12 | N29: =IF($O$32 ="G1", 'G1'!$D36,"") | O29: =IF($O$32 ="G2", 'G2'!$D36,"") | P29: =IF($O$32 ="G3", 'G3'!$D36,"") | Q29: =IF($O$32 ="G4", 'G4'!$D36,"") | R29: =IF($O$32 ="G5", 'G5'!$D36,"") | S29: =IF($O$32 ="G6", 'G6'!$D36,"") | T29: =IF($O$32 ="G7", 'G7'!$D36,"") | U29: =SUM(N29:T29) -> 0 | V29: ='G1'!$D36+'G2'!$D36+'G3'!$D36+'G4'!$D36+'G5'!$D36+'G6'!$D36+'G7'!$D36 -> 0
C30: FMP 13 | D30: ='G1'!AF37+'G2'!AF37+'G3'!AF37+'G4'!AF37+'G5'!AF37+'G6'!AF37+'G7'!AF37 -> 0 | E30: ='G1'!AG37+'G2'!AG37+'G3'!AG37+'G4'!AG37+'G5'!AG37+'G6'!AG37+'G7'!AG37 -> 0 | F30: ='G1'!AH37+'G2'!AH37+'G3'!AH37+'G4'!AH37+'G5'!AH37+'G6'!AH37+'G7'!AH37 -> 0 | G30: ='G1'!AI37+'G2'!AI37+'G3'!AI37+'G4'!AI37+'G5'!AI37+'G6'!AI37+'G7'!AI37 -> 0 | H30: ='G1'!AJ37+'G2'!AJ37+'G3'!AJ37+'G4'!AJ37+'G5'!AJ37+'G6'!AJ37+'G7'!AJ37 -> 0 | I30: =IF(E30=0,, 1-ABS(G30)/E30) | J30: =IF(F30=0,, ABS(H30)/F30) | L30: =C30 -> FMP 13 | N30: =IF($O$32 ="G1", 'G1'!$D37,"") | O30: =IF($O$32 ="G2", 'G2'!$D37,"") | P30: =IF($O$32 ="G3", 'G3'!$D37,"") | Q30: =IF($O$32 ="G4", 'G4'!$D37,"") | R30: =IF($O$32 ="G5", 'G5'!$D37,"") | S30: =IF($O$32 ="G6", 'G6'!$D37,"") | T30: =IF($O$32 ="G7", 'G7'!$D37,"") | U30: =SUM(N30:T30) -> 0 | V30: ='G1'!$D37+'G2'!$D37+'G3'!$D37+'G4'!$D37+'G5'!$D37+'G6'!$D37+'G7'!$D37 -> 0
B32: Stats | C32: Name | D32: Goals | E32: Assists | F32: Blocks | G32: Turns | N32: Current Game | O32: G1
B33: Dodos | L33: Dodos | M33: Introduction
C34: =C4 -> MMP 1 | D34: ='G1'!D50+'G2'!D50+'G3'!D50+'G4'!D50+'G5'!D50+'G6'!D50+'G7'!D50 -> 0 | E34: ='G1'!E50+'G2'!E50+'G3'!E50+'G4'!E50+'G5'!E50+'G6'!E50+'G7'!E50 -> 0 | F34: ='G1'!F50+'G2'!F50+'G3'!F50+'G4'!F50+'G5'!F50+'G6'!F50+'G7'!F50 -> 0 | G34: ='G1'!G50+'G2'!G50+'G3'!G50+'G4'!G50+'G5'!G50+'G6'!G50+'G7'!G50 -> 0 | L34: =L4 -> MMP 1
C35: =C5 -> MMP 2 | D35: ='G1'!D51+'G2'!D51+'G3'!D51+'G4'!D51+'G5'!D51+'G6'!D51+'G7'!D51 -> 0 | E35: ='G1'!E51+'G2'!E51+'G3'!E51+'G4'!E51+'G5'!E51+'G6'!E51+'G7'!E51 -> 0 | F35: ='G1'!F51+'G2'!F51+'G3'!F51+'G4'!F51+'G5'!F51+'G6'!F51+'G7'!F51 -> 0 | G35: ='G1'!G51+'G2'!G51+'G3'!G51+'G4'!G51+'G5'!G51+'G6'!G51+'G7'!G51 -> 0 | L35: =L5 -> MMP 2
C36: =C6 -> MMP 3 | D36: ='G1'!D52+'G2'!D52+'G3'!D52+'G4'!D52+'G5'!D52+'G6'!D52+'G7'!D52 -> 0 | E36: ='G1'!E52+'G2'!E52+'G3'!E52+'G4'!E52+'G5'!E52+'G6'!E52+'G7'!E52 -> 0 | F36: ='G1'!F52+'G2'!F52+'G3'!F52+'G4'!F52+'G5'!F52+'G6'!F52+'G7'!F52 -> 0 | G36: ='G1'!G52+'G2'!G52+'G3'!G52+'G4'!G52+'G5'!G52+'G6'!G52+'G7'!G52 -> 0 | L36: =L6 -> MMP 3
C37: =C7 -> MMP 4 | D37: ='G1'!D53+'G2'!D53+'G3'!D53+'G4'!D53+'G5'!D53+'G6'!D53+'G7'!D53 -> 0 | E37: ='G1'!E53+'G2'!E53+'G3'!E53+'G4'!E53+'G5'!E53+'G6'!E53+'G7'!E53 -> 0 | F37: ='G1'!F53+'G2'!F53+'G3'!F53+'G4'!F53+'G5'!F53+'G6'!F53+'G7'!F53 -> 0 | G37: ='G1'!G53+'G2'!G53+'G3'!G53+'G4'!G53+'G5'!G53+'G6'!G53+'G7'!G53 -> 0 | L37: =L7 -> MMP 4
C38: =C8 -> MMP 5 | D38: ='G1'!D54+'G2'!D54+'G3'!D54+'G4'!D54+'G5'!D54+'G6'!D54+'G7'!D54 -> 0 | E38: ='G1'!E54+'G2'!E54+'G3'!E54+'G4'!E54+'G5'!E54+'G6'!E54+'G7'!E54 -> 0 | F38: ='G1'!F54+'G2'!F54+'G3'!F54+'G4'!F54+'G5'!F54+'G6'!F54+'G7'!F54 -> 0 | G38: ='G1'!G54+'G2'!G54+'G3'!G54+'G4'!G54+'G5'!G54+'G6'!G54+'G7'!G54 -> 0 | L38: =L8 -> MMP 5
C39: =C9 -> MMP 6 | D39: ='G1'!D55+'G2'!D55+'G3'!D55+'G4'!D55+'G5'!D55+'G6'!D55+'G7'!D55 -> 0 | E39: ='G1'!E55+'G2'!E55+'G3'!E55+'G4'!E55+'G5'!E55+'G6'!E55+'G7'!E55 -> 0 | F39: ='G1'!F55+'G2'!F55+'G3'!F55+'G4'!F55+'G5'!F55+'G6'!F55+'G7'!F55 -> 0 | G39: ='G1'!G55+'G2'!G55+'G3'!G55+'G4'!G55+'G5'!G55+'G6'!G55+'G7'!G55 -> 0 | L39: =L9 -> MMP 6
C40: =C10 -> MMP 7 | D40: ='G1'!D56+'G2'!D56+'G3'!D56+'G4'!D56+'G5'!D56+'G6'!D56+'G7'!D56 -> 0 | E40: ='G1'!E56+'G2'!E56+'G3'!E56+'G4'!E56+'G5'!E56+'G6'!E56+'G7'!E56 -> 0 | F40: ='G1'!F56+'G2'!F56+'G3'!F56+'G4'!F56+'G5'!F56+'G6'!F56+'G7'!F56 -> 0 | G40: ='G1'!G56+'G2'!G56+'G3'!G56+'G4'!G56+'G5'!G56+'G6'!G56+'G7'!G56 -> 0 | L40: =L10 -> MMP 7
C41: =C11 -> MMP 8 | D41: ='G1'!D57+'G2'!D57+'G3'!D57+'G4'!D57+'G5'!D57+'G6'!D57+'G7'!D57 -> 0 | E41: ='G1'!E57+'G2'!E57+'G3'!E57+'G4'!E57+'G5'!E57+'G6'!E57+'G7'!E57 -> 0 | F41: ='G1'!F57+'G2'!F57+'G3'!F57+'G4'!F57+'G5'!F57+'G6'!F57+'G7'!F57 -> 0 | G41: ='G1'!G57+'G2'!G57+'G3'!G57+'G4'!G57+'G5'!G57+'G6'!G57+'G7'!G57 -> 0 | L41: =L11 -> MMP 8
C42: =C12 -> MMP 9 | D42: ='G1'!D58+'G2'!D58+'G3'!D58+'G4'!D58+'G5'!D58+'G6'!D58+'G7'!D58 -> 0 | E42: ='G1'!E58+'G2'!E58+'G3'!E58+'G4'!E58+'G5'!E58+'G6'!E58+'G7'!E58 -> 0 | F42: ='G1'!F58+'G2'!F58+'G3'!F58+'G4'!F58+'G5'!F58+'G6'!F58+'G7'!F58 -> 0 | G42: ='G1'!G58+'G2'!G58+'G3'!G58+'G4'!G58+'G5'!G58+'G6'!G58+'G7'!G58 -> 0 | L42: =L12 -> MMP 9
C43: =C13 -> MMP 10 | D43: ='G1'!D59+'G2'!D59+'G3'!D59+'G4'!D59+'G5'!D59+'G6'!D59+'G7'!D59 -> 0 | E43: ='G1'!E59+'G2'!E59+'G3'!E59+'G4'!E59+'G5'!E59+'G6'!E59+'G7'!E59 -> 0 | F43: ='G1'!F59+'G2'!F59+'G3'!F59+'G4'!F59+'G5'!F59+'G6'!F59+'G7'!F59 -> 0 | G43: ='G1'!G59+'G2'!G59+'G3'!G59+'G4'!G59+'G5'!G59+'G6'!G59+'G7'!G59 -> 0 | L43: =L13 -> MMP 10
...

Sheet Sheet4
C2: June Bloom | D2: Rev | E2: FP
B3: Andrew | C3: 32 | D3: 16 | E3: 44 | F3: =SUM(C3:E3) -> 92 | G3: missed half Rev
B4: Bayou | C4: 31 | D4: 35 | E4: 43 | F4: =SUM(C4:E4) -> 109
B5: Caliber (D) | C5: 32 | D5: 32 | E5: 45 | F5: =SUM(C5:E5) -> 109 | G5: Missed a few points at Rev
B6: Chengo (D) | C6: 32 | D6: 30 | E6: 44 | F6: =SUM(C6:E6) -> 106 | G6: Late to Rev
B7: Jack (O) | C7: 31 | D7: 35 | E7: 44 | F7: =SUM(C7:E7) -> 110
B8: Stitch | C8: 31 | D8: 35 | E8: 40 | F8: =SUM(C8:E8) -> 106 | G8: Missed some of FP
B9: Roe (D) | C9: 32 | D9: 34 | E9: 4 | F9: =SUM(C9:E9) -> 70 | G9: Missed most of FP
B10: Paul (D) | C10: 32 | D10: 35 | E10: 43 | F10: =SUM(C10:E10) -> 110
B11: Shu (D) | C11: 31 | D11: 35 | E11: 44 | F11: =SUM(C11:E11) -> 110
B12: Aaron (D) | C12: 19 | D12: 35 | E12: 40 | F12: =SUM(C12:E12) -> 94 | G12: Missed time at June Bloom and FP
B13: Justen (O) | C13: 18 | D13: 35 | E13: 44 | F13: =SUM(C13:E13) -> 97 | G13: Missed June Bloom (1/2}
B14: Prizzma | C14: 0 | D14: 36 | E14: 42 | F14: =SUM(C14:E14) -> 78 | G14: No June Bloom
B15: Maple (O) | C15: 31 | D15: 31 | E15: 42 | F15: =SUM(C15:E15) -> 104 | G15: Late to Rev
B16: Klaw (O) | C16: 31 | D16: 37 | E16: 43 | F16: =SUM(C16:E16) -> 111
B17: Ladle | C17: 32 | D17: 36 | E17: 43 | F17: =SUM(C17:E17) -> 111
B18: Neo | C18: 24 | D18: 0 | E18: 43 | F18: =SUM(C18:E18) -> 67 | G18: No Rev, 1/2 of June Bloom
B19: Lynn (D) | C19: 31 | D19: 36 | E19: 40 | F19: =SUM(C19:E19) -> 107 | G19: Missed a few points at FP
B20: Pike (O) | C20: 31 | D20: 36 | E20: 39 | F20: =SUM(C20:E20) -> 106 | G20: Missed a few points at FP
B21: Puffin | C21: 16 | D21: 0 | E21: 42 | F21: =SUM(C21:E21) -> 58 | G21: Missed time at June Bloom, no Rev
B22: Tonic | C22: 31 | D22: 37 | E22: 43 | F22: =SUM(C22:E22) -> 111
B23: Kipo (D) | C23: 31 | D23: 37 | E23: 43 | F23: =SUM(C23:E23) -> 111
B24: Stratus | C24: 0 | D24: 37 | E24: 43 | F24: =SUM(C24:E24) -> 80 | G24: No June Bloom

Sheet Template
C2: O/D Start | F2: Up/Down | J2: O/D Half | K2: =IF(ISBLANK(D2),"",IF(D2="Offense","D","O")) | N2: Half Cap | O2: 8
C3: MMP | D3: 4 | E3: =IF($D$3=4,3,4) -> 3 | F3: =IF($D$3=4,3,4) -> 3 | G3: =IF($D$3=4,4,3) -> 4 | H3: =IF($D$3=4,4,3) -> 4 | I3: =IF($D$3=4,3,4) -> 3 | J3: =IF($D$3=4,3,4) -> 3 | K3: =IF($D$3=4,4,3) -> 4 | L3: =IF($D$3=4,4,3) -> 4 | M3: =IF($D$3=4,3,4) -> 3 | N3: =IF($D$3=4,3,4) -> 3 | O3: =IF($D$3=4,4,3) -> 4 | P3: =IF($D$3=4,4,3) -> 4 | Q3: =IF($D$3=4,3,4) -> 3 | R3: =IF($D$3=4,3,4) -> 3 | S3: =IF($D$3=4,4,3) -> 4 | T3: =IF($D$3=4,4,3) -> 4 | U3: =IF($D$3=4,3,4) -> 3 | V3: =IF($D$3=4,3,4) -> 3 | W3: =IF($D$3=4,4,3) -> 4 | X3: =IF($D$3=4,4,3) -> 4 | Y3: =IF($D$3=4,3,4) -> 3 | Z3: =IF($D$3=4,3,4) -> 3 | AA3: =IF($D$3=4,4,3) -> 4 | AB3: =IF($D$3=4,4,3) -> 4 | AC3: =IF($D$3=4,3,4) -> 3 | AD3: =IF($D$3=4,3,4) -> 3
C4: FMP | D4: =IF($D$3=3,4,3) -> 3 | E4: =IF($D$4=3,4,3) -> 4 | F4: =IF($D$4=3,4,3) -> 4 | G4: =IF($D$4=3,3,4) -> 3 | H4: =IF($D$4=3,3,4) -> 3 | I4: =IF($D$4=3,4,3) -> 4 | J4: =IF($D$4=3,4,3) -> 4 | K4: =IF($D$4=3,3,4) -> 3 | L4: =IF($D$4=3,3,4) -> 3 | M4: =IF($D$4=3,4,3) -> 4 | N4: =IF($D$4=3,4,3) -> 4 | O4: =IF($D$4=3,3,4) -> 3 | P4: =IF($D$4=3,3,4) -> 3 | Q4: =IF($D$4=3,4,3) -> 4 | R4: =IF($D$4=3,4,3) -> 4 | S4: =IF($D$4=3,3,4) -> 3 | T4: =IF($D$4=3,3,4) -> 3 | U4: =IF($D$4=3,4,3) -> 4 | V4: =IF($D$4=3,4,3) -> 4 | W4: =IF($D$4=3,3,4) -> 3 | X4: =IF($D$4=3,3,4) -> 3 | Y4: =IF($D$4=3,4,3) -> 4 | Z4: =IF($D$4=3,4,3) -> 4 | AA4: =IF($D$4=3,3,4) -> 3 | AB4: =IF($D$4=3,3,4) -> 3 | AC4: =IF($D$4=3,4,3) -> 4 | AD4: =IF($D$4=3,4,3) -> 4
C5: O/D Point | D5: =IF(ISBLANK(D2),,IF(D2="Offense","O","D")) | E5: =IF(ISBLANK(D6),,IF(D6>0,"D","O")) | F5: =IFS(ISBLANK(E6),,AND(E6>=$O$2,E7>=$O$2),IF(E6-D6>0,"D","O"),AND(E7=$O$2,E7-D7>0),$K$2,AND(E6=$O$2,E6-D6>0),$K$2,E6-D6>0,"D",E6-D6<1,"O") | G5: =IFS(ISBLANK(F6),,AND(F6>=$O$2,F7>=$O$2),IF(F6-E6>0,"D","O"),AND(F7=$O$2,F7-E7>0),$K$2,AND(F6=$O$2,F6-E6>0),$K$2,F6-E6>0,"D",F6-E6<1,"O") | H5: =IFS(ISBLANK(G6),,AND(G6>=$O$2,G7>=$O$2),IF(G6-F6>0,"D","O"),AND(G7=$O$2,G7-F7>0),$K$2,AND(G6=$O$2,G6-F6>0),$K$2,G6-F6>0,"D",G6-F6<1,"O") | I5: =IFS(ISBLANK(H6),,AND(H6>=$O$2,H7>=$O$2),IF(H6-G6>0,"D","O"),AND(H7=$O$2,H7-G7>0),$K$2,AND(H6=$O$2,H6-G6>0),$K$2,H6-G6>0,"D",H6-G6<1,"O") | J5: =IFS(ISBLANK(I6),,AND(I6>=$O$2,I7>=$O$2),IF(I6-H6>0,"D","O"),AND(I7=$O$2,I7-H7>0),$K$2,AND(I6=$O$2,I6-H6>0),$K$2,I6-H6>0,"D",I6-H6<1,"O") | K5: =IFS(ISBLANK(J6),,AND(J6>=$O$2,J7>=$O$2),IF(J6-I6>0,"D","O"),AND(J7=$O$2,J7-I7>0),$K$2,AND(J6=$O$2,J6-I6>0),$K$2,J6-I6>0,"D",J6-I6<1,"O") | L5: =IFS(ISBLANK(K6),,AND(K6>=$O$2,K7>=$O$2),IF(K6-J6>0,"D","O"),AND(K7=$O$2,K7-J7>0),$K$2,AND(K6=$O$2,K6-J6>0),$K$2,K6-J6>0,"D",K6-J6<1,"O") | M5: =IFS(ISBLANK(L6),,AND(L6>=$O$2,L7>=$O$2),IF(L6-K6>0,"D","O"),AND(L7=$O$2,L7-K7>0),$K$2,AND(L6=$O$2,L6-K6>0),$K$2,L6-K6>0,"D",L6-K6<1,"O") | ... AD5: =IFS(ISBLANK(AC6),,AND(AC6>=$O$2,AC7>=$O$2),IF(AC6-AB6>0,"D","O"),AND(AC7=$O$2,AC7-AB7>0),$K$2,AND(AC6=$O$2,AC6-AB6>0),$K$2,AC6-AB6>0,"D",AC6-AB6<1,"O")
C6: Score Us | D6: =IF(ISBLANK(D40),IF(ISBLANK(D43), ,0),1) | E6: =IF(ISBLANK(E40),IF(ISBLANK(E43), ,D6),D6+1) | F6: =IF(ISBLANK(F40),IF(ISBLANK(F43), ,E6),E6+1) | G6: =IF(ISBLANK(G40),IF(ISBLANK(G43), ,F6),F6+1) | H6: =IF(ISBLANK(H40),IF(ISBLANK(H43), ,G6),G6+1) | I6: =IF(ISBLANK(I40),IF(ISBLANK(I43), ,H6),H6+1) | J6: =IF(ISBLANK(J40),IF(ISBLANK(J43), ,I6),I6+1) | K6: =IF(ISBLANK(K40),IF(ISBLANK(K43), ,J6),J6+1) | L6: =IF(ISBLANK(L40),IF(ISBLANK(L43), ,K6),K6+1) | ... AD6: =IF(ISBLANK(AD40),IF(ISBLANK(AD43), ,AC6),AC6+1) | AE6: Active? | AF6: Count | AG6: O Count | AH6: D Count | AI6: O Rating | AJ6: D Rating
C7: Score Them | D7: =IF(ISBLANK(D43),IF(ISBLANK(D40), ,0),1) | E7: =IF(ISBLANK(E43),IF(ISBLANK(E40), ,D7),D7+1) | F7: =IF(ISBLANK(F43),IF(ISBLANK(F40), ,E7),E7+1) | G7: =IF(ISBLANK(G43),IF(ISBLANK(G40), ,F7),F7+1) | H7: =IF(ISBLANK(H43),IF(ISBLANK(H40), ,G7),G7+1) | I7: =IF(ISBLANK(I43),IF(ISBLANK(I40), ,H7),H7+1) | J7: =IF(ISBLANK(J43),IF(ISBLANK(J40), ,I7),I7+1) | K7: =IF(ISBLANK(K43),IF(ISBLANK(K40), ,J7),J7+1) | L7: =IF(ISBLANK(L43),IF(ISBLANK(L40), ,K7),K7+1) | ... AD7: =IF(ISBLANK(AD43),IF(ISBLANK(AD40), ,AC7),AC7+1)
A8: Running | B8: Prev Pts | C8: Name
A9: =AF9+B9 -> 0 | C9: =Tourn_Summary!C4 -> MMP 1 | AF9: =SUM(D9:AE9) -> 0 | AG9: =SUMIF($D$6:$AD$6,"=O",D9:AD9) -> 0 | AH9: =SUMIF($D$6:$AD$6,"=D",D9:AD9) -> 0 | AI9: =SUMPRODUCT(D9:AD9,$D$45:$AD$45) -> 0 | AJ9: =SUMPRODUCT(D9:AD9,$D$46:$AD$46) -> 0
A10: =AF10+B10 -> 0 | C10: =Tourn_Summary!C5 -> MMP 2 | AF10: =SUM(D10:AD10) -> 0 | AG10: =SUMIF($D$6:$AD$6,"=O",D10:AD10) -> 0 | AH10: =SUMIF($D$6:$AD$6,"=D",D10:AD10) -> 0 | AI10: =SUMPRODUCT(D10:AD10,$D$45:$AD$45) -> 0 | AJ10: =SUMPRODUCT(D10:AD10,$D$46:$AD$46) -> 0
A11: =AF11+B11 -> 0 | C11: =Tourn_Summary!C6 -> MMP 3 | AF11: =SUM(D11:AD11) -> 0 | AG11: =SUMIF($D$6:$AD$6,"=O",D11:AD11) -> 0 | AH11: =SUMIF($D$6:$AD$6,"=D",D11:AD11) -> 0 | AI11: =SUMPRODUCT(D11:AD11,$D$45:$AD$45) -> 0 | AJ11: =SUMPRODUCT(D11:AD11,$D$46:$AD$46) -> 0
A12: =AF12+B12 -> 0 | C12: =Tourn_Summary!C7 -> MMP 4 | AF12: =SUM(D12:AE12) -> 0 | AG12: =SUMIF($D$6:$AD$6,"=O",D12:AD12) -> 0 | AH12: =SUMIF($D$6:$AD$6,"=D",D12:AD12) -> 0 | AI12: =SUMPRODUCT(D12:AD12,$D$45:$AD$45) -> 0 | AJ12: =SUMPRODUCT(D12:AD12,$D$46:$AD$46) -> 0
A13: =AF13+B13 -> 0 | C13: =Tourn_Summary!C8 -> MMP 5 | AF13: =SUM(D13:AD13) -> 0 | AG13: =SUMIF($D$6:$AD$6,"=O",D13:AD13) -> 0 | AH13: =SUMIF($D$6:$AD$6,"=D",D13:AD13) -> 0 | AI13: =SUMPRODUCT(D13:AD13,$D$45:$AD$45) -> 0 | AJ13: =SUMPRODUCT(D13:AD13,$D$46:$AD$46) -> 0
A14: =AF14+B14 -> 0 | C14: =Tourn_Summary!C9 -> MMP 6 | AF14: =SUM(D14:AD14) -> 0 | AG14: =SUMIF($D$6:$AD$6,"=O",D14:AD14) -> 0 | AH14: =SUMIF($D$6:$AD$6,"=D",D14:AD14) -> 0 | AI14: =SUMPRODUCT(D14:AD14,$D$45:$AD$45) -> 0 | AJ14: =SUMPRODUCT(D14:AD14,$D$46:$AD$46) -> 0
A15: =AF15+B15 -> 0 | C15: =Tourn_Summary!C10 -> MMP 7 | AF15: =SUM(D15:AD15) -> 0 | AG15: =SUMIF($D$6:$AD$6,"=O",D15:AD15) -> 0 | AH15: =SUMIF($D$6:$AD$6,"=D",D15:AD15) -> 0 | AI15: =SUMPRODUCT(D15:AD15,$D$45:$AD$45) -> 0 | AJ15: =SUMPRODUCT(D15:AD15,$D$46:$AD$46) -> 0
A16: =AF16+B16 -> 0 | C16: =Tourn_Summary!C11 -> MMP 8 | AF16: =SUM(D16:AD16) -> 0 | AG16: =SUMIF($D$6:$AD$6,"=O",D16:AD16) -> 0 | AH16: =SUMIF($D$6:$AD$6,"=D",D16:AD16) -> 0 | AI16: =SUMPRODUCT(D16:AD16,$D$45:$AD$45) -> 0 | AJ16: =SUMPRODUCT(D16:AD16,$D$46:$AD$46) -> 0
A17: =AF17+B17 -> 0 | C17: =Tourn_Summary!C12 -> MMP 9 | AF17: =SUM(D17:AD17) -> 0 | AG17: =SUMIF($D$6:$AD$6,"=O",D17:AD17) -> 0 | AH17: =SUMIF($D$6:$AD$6,"=D",D17:AD17) -> 0 | AI17: =SUMPRODUCT(D17:AD17,$D$45:$AD$45) -> 0 | AJ17: =SUMPRODUCT(D17:AD17,$D$46:$AD$46) -> 0
A18: =AF18+B18 -> 0 | C18: =Tourn_Summary!C13 -> MMP 10 | AF18: =SUM(D18:AD18) -> 0 | AG18: =SUMIF($D$6:$AD$6,"=O",D18:AD18) -> 0 | AH18: =SUMIF($D$6:$AD$6,"=D",D18:AD18) -> 0 | AI18: =SUMPRODUCT(D18:AD18,$D$45:$AD$45) -> 0 | AJ18: =SUMPRODUCT(D18:AD18,$D$46:$AD$46) -> 0
A19: =AF19+B19 -> 0 | C19: =Tourn_Summary!C14 -> MMP 11 | AF19: =SUM(D19:AD19) -> 0 | AG19: =SUMIF($D$6:$AD$6,"=O",D19:AD19) -> 0 | AH19: =SUMIF($D$6:$AD$6,"=D",D19:AD19) -> 0 | AI19: =SUMPRODUCT(D19:AD19,$D$45:$AD$45) -> 0 | AJ19: =SUMPRODUCT(D19:AD19,$D$46:$AD$46) -> 0
A20: =AF20+B20 -> 0 | C20: =Tourn_Summary!C15 -> MMP 12 | AF20: =SUM(D20:AD20) -> 0 | AG20: =SUMIF($D$6:$AD$6,"=O",D20:AD20) -> 0 | AH20: =SUMIF($D$6:$AD$6,"=D",D20:AD20) -> 0 | AI20: =SUMPRODUCT(D20:AD20,$D$45:$AD$45) -> 0 | AJ20: =SUMPRODUCT(D20:AD20,$D$46:$AD$46) -> 0
A21: =AF21+B21 -> 0 | C21: =Tourn_Summary!C16 -> MMP 13 | AF21: =SUM(D21:AD21) -> 0 | AG21: =SUMIF($D$6:$AD$6,"=O",D21:AD21) -> 0 | AH21: =SUMIF($D$6:$AD$6,"=D",D21:AD21) -> 0 | AI21: =SUMPRODUCT(D21:AD21,$D$45:$AD$45) -> 0 | AJ21: =SUMPRODUCT(D21:AD21,$D$46:$AD$46) -> 0
C22: Count | D22: =SUM(D9:D21) -> 0 | E22: =SUM(E9:E21) -> 0 | F22: =SUM(F9:F21) -> 0 | G22: =SUM(G9:G21) -> 0 | H22: =SUM(H9:H21) -> 0 | I22: =SUM(I9:I21) -> 0 | J22: =SUM(J9:J21) -> 0 | K22: =SUM(K9:K21) -> 0 | ... AD22: =SUM(AD9:AD21) -> 0
A24: Running | B24: Prev Pts | C24: Name
A25: =AF25+B25 -> 0 | C25: =Tourn_Summary!C18 -> FMP 1 | AF25: =SUM(D25:AD25) -> 0 | AG25: =SUMIF($D$6:$AD$6,"=O",D25:AD25) -> 0 | AH25: =SUMIF($D$6:$AD$6,"=D",D25:AD25) -> 0 | AI25: =SUMPRODUCT(D25:AD25,$D$45:$AD$45) -> 0 | AJ25: =SUMPRODUCT(D25:AD25,$D$46:$AD$46) -> 0
A26: =AF26+B26 -> 0 | C26: =Tourn_Summary!C19 -> FMP 2 | AF26: =SUM(D26:AD26) -> 0 | AG26: =SUMIF($D$6:$AD$6,"=O",D26:AD26) -> 0 | AH26: =SUMIF($D$6:$AD$6,"=D",D26:AD26) -> 0 | AI26: =SUMPRODUCT(D26:AD26,$D$45:$AD$45) -> 0 | AJ26: =SUMPRODUCT(D26:AD26,$D$46:$AD$46) -> 0
A27: =AF27+B27 -> 0 | C27: =Tourn_Summary!C20 -> FMP 3 | AF27: =SUM(D27:AD27) -> 0 | AG27: =SUMIF($D$6:$AD$6,"=O",D27:AD27) -> 0 | AH27: =SUMIF($D$6:$AD$6,"=D",D27:AD27) -> 0 | AI27: =SUMPRODUCT(D27:AD27,$D$45:$AD$45) -> 0 | AJ27: =SUMPRODUCT(D27:AD27,$D$46:$AD$46) -> 0
A28: =AF28+B28 -> 0 | C28: =Tourn_Summary!C21 -> FMP 4 | AF28: =SUM(D28:AD28) -> 0 | AG28: =SUMIF($D$6:$AD$6,"=O",D28:AD28) -> 0 | AH28: =SUMIF($D$6:$AD$6,"=D",D28:AD28) -> 0 | AI28: =SUMPRODUCT(D28:AD28,$D$45:$AD$45) -> 0 | AJ28: =SUMPRODUCT(D28:AD28,$D$46:$AD$46) -> 0
A29: =AF29+B29 -> 0 | C29: =Tourn_Summary!C22 -> FMP 5 | AF29: =SUM(D29:AD29) -> 0 | AG29: =SUMIF($D$6:$AD$6,"=O",D29:AD29) -> 0 | AH29: =SUMIF($D$6:$AD$6,"=D",D29:AD29) -> 0 | AI29: =SUMPRODUCT(D29:AD29,$D$45:$AD$45) -> 0 | AJ29: =SUMPRODUCT(D29:AD29,$D$46:$AD$46) -> 0
A30: =AF30+B30 -> 0 | C30: =Tourn_Summary!C23 -> FMP 6 | AF30: =SUM(D30:AD30) -> 0 | AG30: =SUMIF($D$6:$AD$6,"=O",D30:AD30) -> 0 | AH30: =SUMIF($D$6:$AD$6,"=D",D30:AD30) -> 0 | AI30: =SUMPRODUCT(D30:AD30,$D$45:$AD$45) -> 0 | AJ30: =SUMPRODUCT(D30:AD30,$D$46:$AD$46) -> 0
A31: =AF31+B31 -> 0 | C31: =Tourn_Summary!C24 -> FMP 7 | AF31: =SUM(D31:AD31) -> 0 | AG31: =SUMIF($D$6:$AD$6,"=O",D31:AD31) -> 0 | AH31: =SUMIF($D$6:$AD$6,"=D",D31:AD31) -> 0 | AI31: =SUMPRODUCT(D31:AD31,$D$45:$AD$45) -> 0 | AJ31: =SUMPRODUCT(D31:AD31,$D$46:$AD$46) -> 0
A32: =AF32+B32 -> 0 | C32: =Tourn_Summary!C25 -> FMP 8 | AF32: =SUM(D32:AD32) -> 0 | AG32: =SUMIF($D$6:$AD$6,"=O",D32:AD32) -> 0 | AH32: =SUMIF($D$6:$AD$6,"=D",D32:AD32) -> 0 | AI32: =SUMPRODUCT(D32:AD32,$D$45:$AD$45) -> 0 | AJ32: =SUMPRODUCT(D32:AD32,$D$46:$AD$46) -> 0
A33: =AF33+B33 -> 0 | C33: =Tourn_Summary!C26 -> FMP 9 | AF33: =SUM(D33:AD33) -> 0 | AG33: =SUMIF($D$6:$AD$6,"=O",D33:AD33) -> 0 | AH33: =SUMIF($D$6:$AD$6,"=D",D33:AD33) -> 0 | AI33: =SUMPRODUCT(D33:AD33,$D$45:$AD$45) -> 0 | AJ33: =SUMPRODUCT(D33:AD33,$D$46:$AD$46) -> 0
A34: =AF34+B34 -> 0 | C34: =Tourn_Summary!C27 -> FMP 10 | AF34: =SUM(D34:AD34) -> 0 | AG34: =SUMIF($D$6:$AD$6,"=O",D34:AD34) -> 0 | AH34: =SUMIF($D$6:$AD$6,"=D",D34:AD34) -> 0 | AI34: =SUMPRODUCT(D34:AD34,$D$45:$AD$45) -> 0 | AJ34: =SUMPRODUCT(D34:AD34,$D$46:$AD$46) -> 0
A35: =AF35+B35 -> 0 | C35: =Tourn_Summary!C28 -> FMP 11 | AF35: =SUM(D35:AD35) -> 0 | AG35: =SUMIF($D$6:$AD$6,"=O",D35:AD35) -> 0 | AH35: =SUMIF($D$6:$AD$6,"=D",D35:AD35) -> 0 | AI35: =SUMPRODUCT(D35:AD35,$D$45:$AD$45) -> 0 | AJ35: =SUMPRODUCT(D35:AD35,$D$46:$AD$46) -> 0
A36: =AF36+B36 -> 0 | C36: =Tourn_Summary!C29 -> FMP 12 | AF36: =SUM(D36:AD36) -> 0 | AG36: =SUMIF($D$6:$AD$6,"=O",D36:AD36) -> 0 | AH36: =SUMIF($D$6:$AD$6,"=D",D36:AD36) -> 0 | AI36: =SUMPRODUCT(D36:AD36,$D$45:$AD$45) -> 0 | AJ36: =SUMPRODUCT(D36:AD36,$D$46:$AD$46) -> 0
A37: =AF37+B37 -> 0 | C37: =Tourn_Summary!C30 -> FMP 13 | AF37: =SUM(D37:AD37) -> 0 | AG37: =SUMIF($D$6:$AD$6,"=O",D37:AD37) -> 0 | AH37: =SUMIF($D$6:$AD$6,"=D",D37:AD37) -> 0 | AI37: =SUMPRODUCT(D37:AD37,$D$45:$AD$45) -> 0 | AJ37: =SUMPRODUCT(D37:AD37,$D$46:$AD$46) -> 0
C38: Count | D38: =SUM(D25:D37) -> 0 | E38: =SUM(E25:E37) -> 0 | F38: =SUM(F25:F37) -> 0 | G38: =SUM(G25:G37) -> 0 | H38: =SUM(H25:H37) -> 0 | I38: =SUM(I25:I37) -> 0 | J38: =SUM(J25:J37) -> 0 | K38: =SUM(K25:K37) -> 0 | ... AD38: =SUM(AD25:AD37) -> 0
C40: Goal
C41: Assist
C43: Opp Goal
AF44: Rating Total | AG44: O/D Total
...

Sheet G1
C2: O/D Start | F2: Up/Down | J2: O/D Half | K2: =IF(ISBLANK(D2),"",IF(D2="Offense","D","O")) | N2: Half Cap | O2: 7
C3: MMP | D3: 3 | E3: =IF($D$3=4,3,4) -> 4 | F3: =IF($D$3=4,3,4) -> 4 | G3: =IF($D$3=4,4,3) -> 3 | H3: =IF($D$3=4,4,3) -> 3 | I3: =IF($D$3=4,3,4) -> 4 | J3: =IF($D$3=4,3,4) -> 4 | K3: =IF($D$3=4,4,3) -> 3 | L3: =IF($D$3=4,4,3) -> 3 | M3: =IF($D$3=4,3,4) -> 4 | N3: =IF($D$3=4,3,4) -> 4 | O3: =IF($D$3=4,4,3) -> 3 | P3: =IF($D$3=4,4,3) -> 3 | Q3: =IF($D$3=4,3,4) -> 4 | R3: =IF($D$3=4,3,4) -> 4 | S3: =IF($D$3=4,4,3) -> 3 | T3: =IF($D$3=4,4,3) -> 3 | U3: =IF($D$3=4,3,4) -> 4 | V3: =IF($D$3=4,3,4) -> 4 | W3: =IF($D$3=4,4,3) -> 3 | X3: =IF($D$3=4,4,3) -> 3 | Y3: =IF($D$3=4,3,4) -> 4 | Z3: =IF($D$3=4,3,4) -> 4 | AA3: =IF($D$3=4,4,3) -> 3 | AB3: =IF($D$3=4,4,3) -> 3 | AC3: =IF($D$3=4,3,4) -> 4 | AD3: =IF($D$3=4,3,4) -> 4
C4: FMP | D4: =IF($D$3=3,4,3) -> 4 | E4: =IF($D$4=3,4,3) -> 3 | F4: =IF($D$4=3,4,3) -> 3 | G4: =IF($D$4=3,3,4) -> 4 | H4: =IF($D$4=3,3,4) -> 4 | I4: =IF($D$4=3,4,3) -> 3 | J4: =IF($D$4=3,4,3) -> 3 | K4: =IF($D$4=3,3,4) -> 4 | L4: =IF($D$4=3,3,4) -> 4 | M4: =IF($D$4=3,4,3) -> 3 | N4: =IF($D$4=3,4,3) -> 3 | O4: =IF($D$4=3,3,4) -> 4 | P4: =IF($D$4=3,3,4) -> 4 | Q4: =IF($D$4=3,4,3) -> 3 | R4: =IF($D$4=3,4,3) -> 3 | S4: =IF($D$4=3,3,4) -> 4 | T4: =IF($D$4=3,3,4) -> 4 | U4: =IF($D$4=3,4,3) -> 3 | V4: =IF($D$4=3,4,3) -> 3 | W4: =IF($D$4=3,3,4) -> 4 | X4: =IF($D$4=3,3,4) -> 4 | Y4: =IF($D$4=3,4,3) -> 3 | Z4: =IF($D$4=3,4,3) -> 3 | AA4: =IF($D$4=3,3,4) -> 4 | AB4: =IF($D$4=3,3,4) -> 4 | AC4: =IF($D$4=3,4,3) -> 3 | AD4: =IF($D$4=3,4,3) -> 3
C5: O/D Point | D5: =IF(ISBLANK(D2),,IF(D2="Offense","O","D")) | E5: =IF(ISBLANK(D6),,IF(D6>0,"D","O")) | F5: =IFS(ISBLANK(E6),,AND(E6>=$O$2,E7>=$O$2),IF(E6-D6>0,"D","O"),AND(E7=$O$2,E7-D7>0),$K$2,AND(E6=$O$2,E6-D6>0),$K$2,E6-D6>0,"D",E6-D6<1,"O") | G5: =IFS(ISBLANK(F6),,AND(F6>=$O$2,F7>=$O$2),IF(F6-E6>0,"D","O"),AND(F7=$O$2,F7-E7>0),$K$2,AND(F6=$O$2,F6-E6>0),$K$2,F6-E6>0,"D",F6-E6<1,"O") | H5: =IFS(ISBLANK(G6),,AND(G6>=$O$2,G7>=$O$2),IF(G6-F6>0,"D","O"),AND(G7=$O$2,G7-F7>0),$K$2,AND(G6=$O$2,G6-F6>0),$K$2,G6-F6>0,"D",G6-F6<1,"O") | I5: =IFS(ISBLANK(H6),,AND(H6>=$O$2,H7>=$O$2),IF(H6-G6>0,"D","O"),AND(H7=$O$2,H7-G7>0),$K$2,AND(H6=$O$2,H6-G6>0),$K$2,H6-G6>0,"D",H6-G6<1,"O") | J5: =IFS(ISBLANK(I6),,AND(I6>=$O$2,I7>=$O$2),IF(I6-H6>0,"D","O"),AND(I7=$O$2,I7-H7>0),$K$2,AND(I6=$O$2,I6-H6>0),$K$2,I6-H6>0,"D",I6-H6<1,"O") | K5: =IFS(ISBLANK(J6),,AND(J6>=$O$2,J7>=$O$2),IF(J6-I6>0,"D","O"),AND(J7=$O$2,J7-I7>0),$K$2,AND(J6=$O$2,J6-I6>0),$K$2,J6-I6>0,"D",J6-I6<1,"O") | L5: =IFS(ISBLANK(K6),,AND(K6>=$O$2,K7>=$O$2),IF(K6-J6>0,"D","O"),AND(K7=$O$2,K7-J7>0),$K$2,AND(K6=$O$2,K6-J6>0),$K$2,K6-J6>0,"D",K6-J6<1,"O") | M5: =IFS(ISBLANK(L6),,AND(L6>=$O$2,L7>=$O$2),IF(L6-K6>0,"D","O"),AND(L7=$O$2,L7-K7>0),$K$2,AND(L6=$O$2,L6-K6>0),$K$2,L6-K6>0,"D",L6-K6<1,"O") | ... AD5: =IFS(ISBLANK(AC6),,AND(AC6>=$O$2,AC7>=$O$2),IF(AC6-AB6>0,"D","O"),AND(AC7=$O$2,AC7-AB7>0),$K$2,AND(AC6=$O$2,AC6-AB6>0),$K$2,AC6-AB6>0,"D",AC6-AB6<1,"O")
C6: Score Us | D6: =IF(ISBLANK(D40),IF(ISBLANK(D43), ,0),1) | E6: =IF(ISBLANK(E40),IF(ISBLANK(E43), ,D6),D6+1) | F6: =IF(ISBLANK(F40),IF(ISBLANK(F43), ,E6),E6+1) | G6: =IF(ISBLANK(G40),IF(ISBLANK(G43), ,F6),F6+1) | H6: =IF(ISBLANK(H40),IF(ISBLANK(H43), ,G6),G6+1) | I6: =IF(ISBLANK(I40),IF(ISBLANK(I43), ,H6),H6+1) | J6: =IF(ISBLANK(J40),IF(ISBLANK(J43), ,I6),I6+1) | K6: =IF(ISBLANK(K40),IF(ISBLANK(K43), ,J6),J6+1) | L6: =IF(ISBLANK(L40),IF(ISBLANK(L43), ,K6),K6+1) | ... AD6: =IF(ISBLANK(AD40),IF(ISBLANK(AD43), ,AC6),AC6+1) | AE6: Active? | AF6: Count | AG6: O Count | AH6: D Count | AI6: O Rating | AJ6: D Rating
C7: Score Them | D7: =IF(ISBLANK(D43),IF(ISBLANK(D40), ,0),1) | E7: =IF(ISBLANK(E43),IF(ISBLANK(E40), ,D7),D7+1) | F7: =IF(ISBLANK(F43),IF(ISBLANK(F40), ,E7),E7+1) | G7: =IF(ISBLANK(G43),IF(ISBLANK(G40), ,F7),F7+1) | H7: =IF(ISBLANK(H43),IF(ISBLANK(H40), ,G7),G7+1) | I7: =IF(ISBLANK(I43),IF(ISBLANK(I40), ,H7),H7+1) | J7: =IF(ISBLANK(J43),IF(ISBLANK(J40), ,I7),I7+1) | K7: =IF(ISBLANK(K43),IF(ISBLANK(K40), ,J7),J7+1) | L7: =IF(ISBLANK(L43),IF(ISBLANK(L40), ,K7),K7+1) | ... AD7: =IF(ISBLANK(AD43),IF(ISBLANK(AD40), ,AC7),AC7+1)
A8: Running | B8: Prev Pts | C8: Name
A9: =AF9+B9 -> 0 | C9: =Tourn_Summary!C4 -> MMP 1 | AF9: =SUM(D9:AD9) -> 0 | AG9: =SUMIF($D$5:$AD$5,"=O",D9:AD9) -> 0 | AH9: =SUMIF($D$5:$AD$5,"=D",D9:AD9) -> 0 | AI9: =SUMPRODUCT(D9:AD9,$D$45:$AD$45) -> 0 | AJ9: =SUMPRODUCT(D9:AD9,$D$46:$AD$46) -> 0
A10: =AF10+B10 -> 0 | C10: =Tourn_Summary!C5 -> MMP 2 | AF10: =SUM(D10:AD10) -> 0 | AG10: =SUMIF($D$5:$AD$5,"=O",D10:AD10) -> 0 | AH10: =SUMIF($D$5:$AD$5,"=D",D10:AD10) -> 0 | AI10: =SUMPRODUCT(D10:AD10,$D$45:$AD$45) -> 0 | AJ10: =SUMPRODUCT(D10:AD10,$D$46:$AD$46) -> 0
A11: =AF11+B11 -> 0 | C11: =Tourn_Summary!C6 -> MMP 3 | AF11: =SUM(D11:AD11) -> 0 | AG11: =SUMIF($D$5:$AD$5,"=O",D11:AD11) -> 0 | AH11: =SUMIF($D$5:$AD$5,"=D",D11:AD11) -> 0 | AI11: =SUMPRODUCT(D11:AD11,$D$45:$AD$45) -> 0 | AJ11: =SUMPRODUCT(D11:AD11,$D$46:$AD$46) -> 0
A12: =AF12+B12 -> 0 | C12: =Tourn_Summary!C7 -> MMP 4 | AF12: =SUM(D12:AD12) -> 0 | AG12: =SUMIF($D$5:$AD$5,"=O",D12:AD12) -> 0 | AH12: =SUMIF($D$5:$AD$5,"=D",D12:AD12) -> 0 | AI12: =SUMPRODUCT(D12:AD12,$D$45:$AD$45) -> 0 | AJ12: =SUMPRODUCT(D12:AD12,$D$46:$AD$46) -> 0
A13: =AF13+B13 -> 0 | C13: =Tourn_Summary!C8 -> MMP 5 | AF13: =SUM(D13:AD13) -> 0 | AG13: =SUMIF($D$5:$AD$5,"=O",D13:AD13) -> 0 | AH13: =SUMIF($D$5:$AD$5,"=D",D13:AD13) -> 0 | AI13: =SUMPRODUCT(D13:AD13,$D$45:$AD$45) -> 0 | AJ13: =SUMPRODUCT(D13:AD13,$D$46:$AD$46) -> 0
A14: =AF14+B14 -> 0 | C14: =Tourn_Summary!C9 -> MMP 6 | AF14: =SUM(D14:AD14) -> 0 | AG14: =SUMIF($D$5:$AD$5,"=O",D14:AD14) -> 0 | AH14: =SUMIF($D$5:$AD$5,"=D",D14:AD14) -> 0 | AI14: =SUMPRODUCT(D14:AD14,$D$45:$AD$45) -> 0 | AJ14: =SUMPRODUCT(D14:AD14,$D$46:$AD$46) -> 0
A15: =AF15+B15 -> 0 | C15: =Tourn_Summary!C10 -> MMP 7 | AF15: =SUM(D15:AD15) -> 0 | AG15: =SUMIF($D$5:$AD$5,"=O",D15:AD15) -> 0 | AH15: =SUMIF($D$5:$AD$5,"=D",D15:AD15) -> 0 | AI15: =SUMPRODUCT(D15:AD15,$D$45:$AD$45) -> 0 | AJ15: =SUMPRODUCT(D15:AD15,$D$46:$AD$46) -> 0
A16: =AF16+B16 -> 0 | C16: =Tourn_Summary!C11 -> MMP 8 | AF16: =SUM(D16:AD16) -> 0 | AG16: =SUMIF($D$5:$AD$5,"=O",D16:AD16) -> 0 | AH16: =SUMIF($D$5:$AD$5,"=D",D16:AD16) -> 0 | AI16: =SUMPRODUCT(D16:AD16,$D$45:$AD$45) -> 0 | AJ16: =SUMPRODUCT(D16:AD16,$D$46:$AD$46) -> 0
A17: =AF17+B17 -> 0 | C17: =Tourn_Summary!C12 -> MMP 9 | AF17: =SUM(D17:AD17) -> 0 | AG17: =SUMIF($D$5:$AD$5,"=O",D17:AD17) -> 0 | AH17: =SUMIF($D$5:$AD$5,"=D",D17:AD17) -> 0 | AI17: =SUMPRODUCT(D17:AD17,$D$45:$AD$45) -> 0 | AJ17: =SUMPRODUCT(D17:AD17,$D$46:$AD$46) -> 0
A18: =AF18+B18 -> 0 | C18: =Tourn_Summary!C13 -> MMP 10 | AF18: =SUM(D18:AD18) -> 0 | AG18: =SUMIF($D$5:$AD$5,"=O",D18:AD18) -> 0 | AH18: =SUMIF($D$5:$AD$5,"=D",D18:AD18) -> 0 | AI18: =SUMPRODUCT(D18:AD18,$D$45:$AD$45) -> 0 | AJ18: =SUMPRODUCT(D18:AD18,$D$46:$AD$46) -> 0
A19: =AF19+B19 -> 0 | C19: =Tourn_Summary!C14 -> MMP 11 | AF19: =SUM(D19:AD19) -> 0 | AG19: =SUMIF($D$5:$AD$5,"=O",D19:AD19) -> 0 | AH19: =SUMIF($D$5:$AD$5,"=D",D19:AD19) -> 0 | AI19: =SUMPRODUCT(D19:AD19,$D$45:$AD$45) -> 0 | AJ19: =SUMPRODUCT(D19:AD19,$D$46:$AD$46) -> 0
A20: =AF20+B20 -> 0 | C20: =Tourn_Summary!C15 -> MMP 12 | AF20: =SUM(D20:AD20) -> 0 | AG20: =SUMIF($D$5:$AD$5,"=O",D20:AD20) -> 0 | AH20: =SUMIF($D$5:$AD$5,"=D",D20:AD20) -> 0 | AI20: =SUMPRODUCT(D20:AD20,$D$45:$AD$45) -> 0 | AJ20: =SUMPRODUCT(D20:AD20,$D$46:$AD$46) -> 0
A21: =AF21+B21 -> 0 | C21: =Tourn_Summary!C16 -> MMP 13 | AF21: =SUM(D21:AD21) -> 0 | AG21: =SUMIF($D$5:$AD$5,"=O",D21:AD21) -> 0 | AH21: =SUMIF($D$5:$AD$5,"=D",D21:AD21) -> 0 | AI21: =SUMPRODUCT(D21:AD21,$D$45:$AD$45) -> 0 | AJ21: =SUMPRODUCT(D21:AD21,$D$46:$AD$46) -> 0
C22: Count | D22: =SUM(D9:D21) -> 0 | E22: =SUM(E9:E21) -> 0 | F22: =SUM(F9:F21) -> 0 | G22: =SUM(G9:G21) -> 0 | H22: =SUM(H9:H21) -> 0 | I22: =SUM(I9:I21) -> 0 | J22: =SUM(J9:J21) -> 0 | K22: =SUM(K9:K21) -> 0 | ... AD22: =SUM(AD9:AD21) -> 0
A24: Running | B24: Prev Pts | C24: Name
A25: =AF25+B25 -> 0 | C25: =Tourn_Summary!C18 -> FMP 1 | AF25: =SUM(D25:AD25) -> 0 | AG25: =SUMIF($D$5:$AD$5,"=O",D25:AD25) -> 0 | AH25: =SUMIF($D$5:$AD$5,"=D",D25:AD25) -> 0 | AI25: =SUMPRODUCT(D25:AD25,$D$45:$AD$45) -> 0 | AJ25: =SUMPRODUCT(D25:AD25,$D$46:$AD$46) -> 0
A26: =AF26+B26 -> 0 | C26: =Tourn_Summary!C19 -> FMP 2 | AF26: =SUM(D26:AD26) -> 0 | AG26: =SUMIF($D$5:$AD$5,"=O",D26:AD26) -> 0 | AH26: =SUMIF($D$5:$AD$5,"=D",D26:AD26) -> 0 | AI26: =SUMPRODUCT(D26:AD26,$D$45:$AD$45) -> 0 | AJ26: =SUMPRODUCT(D26:AD26,$D$46:$AD$46) -> 0
A27: =AF27+B27 -> 0 | C27: =Tourn_Summary!C20 -> FMP 3 | AF27: =SUM(D27:AD27) -> 0 | AG27: =SUMIF($D$5:$AD$5,"=O",D27:AD27) -> 0 | AH27: =SUMIF($D$5:$AD$5,"=D",D27:AD27) -> 0 | AI27: =SUMPRODUCT(D27:AD27,$D$45:$AD$45) -> 0 | AJ27: =SUMPRODUCT(D27:AD27,$D$46:$AD$46) -> 0
A28: =AF28+B28 -> 0 | C28: =Tourn_Summary!C21 -> FMP 4 | AF28: =SUM(D28:AD28) -> 0 | AG28: =SUMIF($D$5:$AD$5,"=O",D28:AD28) -> 0 | AH28: =SUMIF($D$5:$AD$5,"=D",D28:AD28) -> 0 | AI28: =SUMPRODUCT(D28:AD28,$D$45:$AD$45) -> 0 | AJ28: =SUMPRODUCT(D28:AD28,$D$46:$AD$46) -> 0
A29: =AF29+B29 -> 0 | C29: =Tourn_Summary!C22 -> FMP 5 | AF29: =SUM(D29:AD29) -> 0 | AG29: =SUMIF($D$5:$AD$5,"=O",D29:AD29) -> 0 | AH29: =SUMIF($D$5:$AD$5,"=D",D29:AD29) -> 0 | AI29: =SUMPRODUCT(D29:AD29,$D$45:$AD$45) -> 0 | AJ29: =SUMPRODUCT(D29:AD29,$D$46:$AD$46) -> 0
A30: =AF30+B30 -> 0 | C30: =Tourn_Summary!C23 -> FMP 6 | AF30: =SUM(D30:AD30) -> 0 | AG30: =SUMIF($D$5:$AD$5,"=O",D30:AD30) -> 0 | AH30: =SUMIF($D$5:$AD$5,"=D",D30:AD30) -> 0 | AI30: =SUMPRODUCT(D30:AD30,$D$45:$AD$45) -> 0 | AJ30: =SUMPRODUCT(D30:AD30,$D$46:$AD$46) -> 0
A31: =AF31+B31 -> 0 | C31: =Tourn_Summary!C24 -> FMP 7 | AF31: =SUM(D31:AD31) -> 0 | AG31: =SUMIF($D$5:$AD$5,"=O",D31:AD31) -> 0 | AH31: =SUMIF($D$5:$AD$5,"=D",D31:AD31) -> 0 | AI31: =SUMPRODUCT(D31:AD31,$D$45:$AD$45) -> 0 | AJ31: =SUMPRODUCT(D31:AD31,$D$46:$AD$46) -> 0
A32: =AF32+B32 -> 0 | C32: =Tourn_Summary!C25 -> FMP 8 | AF32: =SUM(D32:AD32) -> 0 | AG32: =SUMIF($D$5:$AD$5,"=O",D32:AD32) -> 0 | AH32: =SUMIF($D$5:$AD$5,"=D",D32:AD32) -> 0 | AI32: =SUMPRODUCT(D32:AD32,$D$45:$AD$45) -> 0 | AJ32: =SUMPRODUCT(D32:AD32,$D$46:$AD$46) -> 0
A33: =AF33+B33 -> 0 | C33: =Tourn_Summary!C26 -> FMP 9 | AF33: =SUM(D33:AD33) -> 0 | AG33: =SUMIF($D$5:$AD$5,"=O",D33:AD33) -> 0 | AH33: =SUMIF($D$5:$AD$5,"=D",D33:AD33) -> 0 | AI33: =SUMPRODUCT(D33:AD33,$D$45:$AD$45) -> 0 | AJ33: =SUMPRODUCT(D33:AD33,$D$46:$AD$46) -> 0
A34: =AF34+B34 -> 0 | C34: =Tourn_Summary!C27 -> FMP 10 | AF34: =SUM(D34:AD34) -> 0 | AG34: =SUMIF($D$5:$AD$5,"=O",D34:AD34) -> 0 | AH34: =SUMIF($D$5:$AD$5,"=D",D34:AD34) -> 0 | AI34: =SUMPRODUCT(D34:AD34,$D$45:$AD$45) -> 0 | AJ34: =SUMPRODUCT(D34:AD34,$D$46:$AD$46) -> 0
A35: =AF35+B35 -> 0 | C35: =Tourn_Summary!C28 -> FMP 11 | AF35: =SUM(D35:AD35) -> 0 | AG35: =SUMIF($D$5:$AD$5,"=O",D35:AD35) -> 0 | AH35: =SUMIF($D$5:$AD$5,"=D",D35:AD35) -> 0 | AI35: =SUMPRODUCT(D35:AD35,$D$45:$AD$45) -> 0 | AJ35: =SUMPRODUCT(D35:AD35,$D$46:$AD$46) -> 0
A36: =AF36+B36 -> 0 | C36: =Tourn_Summary!C29 -> FMP 12 | AF36: =SUM(D36:AD36) -> 0 | AG36: =SUMIF($D$5:$AD$5,"=O",D36:AD36) -> 0 | AH36: =SUMIF($D$5:$AD$5,"=D",D36:AD36) -> 0 | AI36: =SUMPRODUCT(D36:AD36,$D$45:$AD$45) -> 0 | AJ36: =SUMPRODUCT(D36:AD36,$D$46:$AD$46) -> 0
A37: =AF37+B37 -> 0 | C37: =Tourn_Summary!C30 -> FMP 13 | AF37: =SUM(D37:AD37) -> 0 | AG37: =SUMIF($D$6:$AD$6,"=O",D37:AD37) -> 0 | AH37: =SUMIF($D$6:$AD$6,"=D",D37:AD37) -> 0 | AI37: =SUMPRODUCT(D37:AD37,$D$45:$AD$45) -> 0 | AJ37: =SUMPRODUCT(D37:AD37,$D$46:$AD$46) -> 0
C38: Count | D38: =SUM(D25:D37) -> 0 | E38: =SUM(E25:E37) -> 0 | F38: =SUM(F25:F37) -> 0 | G38: =SUM(G25:G37) -> 0 | H38: =SUM(H25:H37) -> 0 | I38: =SUM(I25:I37) -> 0 | J38: =SUM(J25:J37) -> 0 | K38: =SUM(K25:K37) -> 0 | ... AD38: =SUM(AD25:AD37) -> 0
C40: Goal
C41: Assist
C43: Opp Goal
AF44: Rating Total | AG44: O/D Total
...

Sheet G2
C2: O/D Start | F2: Up/Down | J2: O/D Half | K2: =IF(ISBLANK(D2),"",IF(D2="Offense","D","O")) | N2: Half Cap | O2: 7
C3: MMP | D3: 4 | E3: =IF($D$3=4,3,4) -> 3 | F3: =IF($D$3=4,3,4) -> 3 | G3: =IF($D$3=4,4,3) -> 4 | H3: =IF($D$3=4,4,3) -> 4 | I3: =IF($D$3=4,3,4) -> 3 | J3: =IF($D$3=4,3,4) -> 3 | K3: =IF($D$3=4,4,3) -> 4 | L3: =IF($D$3=4,4,3) -> 4 | M3: =IF($D$3=4,3,4) -> 3 | N3: =IF($D$3=4,3,4) -> 3 | O3: =IF($D$3=4,4,3) -> 4 | P3: =IF($D$3=4,4,3) -> 4 | Q3: =IF($D$3=4,3,4) -> 3 | R3: =IF($D$3=4,3,4) -> 3 | S3: =IF($D$3=4,4,3) -> 4 | T3: =IF($D$3=4,4,3) -> 4 | U3: =IF($D$3=4,3,4) -> 3 | V3: =IF($D$3=4,3,4) -> 3 | W3: =IF($D$3=4,4,3) -> 4 | X3: =IF($D$3=4,4,3) -> 4 | Y3: =IF($D$3=4,3,4) -> 3 | Z3: =IF($D$3=4,3,4) -> 3 | AA3: =IF($D$3=4,4,3) -> 4 | AB3: =IF($D$3=4,4,3) -> 4 | AC3: =IF($D$3=4,3,4) -> 3 | AD3: =IF($D$3=4,3,4) -> 3
C4: FMP | D4: =IF($D$3=3,4,3) -> 3 | E4: =IF($D$4=3,4,3) -> 4 | F4: =IF($D$4=3,4,3) -> 4 | G4: =IF($D$4=3,3,4) -> 3 | H4: =IF($D$4=3,3,4) -> 3 | I4: =IF($D$4=3,4,3) -> 4 | J4: =IF($D$4=3,4,3) -> 4 | K4: =IF($D$4=3,3,4) -> 3 | L4: =IF($D$4=3,3,4) -> 3 | M4: =IF($D$4=3,4,3) -> 4 | N4: =IF($D$4=3,4,3) -> 4 | O4: =IF($D$4=3,3,4) -> 3 | P4: =IF($D$4=3,3,4) -> 3 | Q4: =IF($D$4=3,4,3) -> 4 | R4: =IF($D$4=3,4,3) -> 4 | S4: =IF($D$4=3,3,4) -> 3 | T4: =IF($D$4=3,3,4) -> 3 | U4: =IF($D$4=3,4,3) -> 4 | V4: =IF($D$4=3,4,3) -> 4 | W4: =IF($D$4=3,3,4) -> 3 | X4: =IF($D$4=3,3,4) -> 3 | Y4: =IF($D$4=3,4,3) -> 4 | Z4: =IF($D$4=3,4,3) -> 4 | AA4: =IF($D$4=3,3,4) -> 3 | AB4: =IF($D$4=3,3,4) -> 3 | AC4: =IF($D$4=3,4,3) -> 4 | AD4: =IF($D$4=3,4,3) -> 4
C5: O/D Point | D5: =IF(ISBLANK(D2),,IF(D2="Offense","O","D")) | E5: =IF(ISBLANK(D6),,IF(D6>0,"D","O")) | F5: =IFS(ISBLANK(E6),,AND(E6>=$O$2,E7>=$O$2),IF(E6-D6>0,"D","O"),AND(E7=$O$2,E7-D7>0),$K$2,AND(E6=$O$2,E6-D6>0),$K$2,E6-D6>0,"D",E6-D6<1,"O") | G5: =IFS(ISBLANK(F6),,AND(F6>=$O$2,F7>=$O$2),IF(F6-E6>0,"D","O"),AND(F7=$O$2,F7-E7>0),$K$2,AND(F6=$O$2,F6-E6>0),$K$2,F6-E6>0,"D",F6-E6<1,"O") | H5: =IFS(ISBLANK(G6),,AND(G6>=$O$2,G7>=$O$2),IF(G6-F6>0,"D","O"),AND(G7=$O$2,G7-F7>0),$K$2,AND(G6=$O$2,G6-F6>0),$K$2,G6-F6>0,"D",G6-F6<1,"O") | I5: =IFS(ISBLANK(H6),,AND(H6>=$O$2,H7>=$O$2),IF(H6-G6>0,"D","O"),AND(H7=$O$2,H7-G7>0),$K$2,AND(H6=$O$2,H6-G6>0),$K$2,H6-G6>0,"D",H6-G6<1,"O") | J5: =IFS(ISBLANK(I6),,AND(I6>=$O$2,I7>=$O$2),IF(I6-H6>0,"D","O"),AND(I7=$O$2,I7-H7>0),$K$2,AND(I6=$O$2,I6-H6>0),$K$2,I6-H6>0,"D",I6-H6<1,"O") | K5: =IFS(ISBLANK(J6),,AND(J6>=$O$2,J7>=$O$2),IF(J6-I6>0,"D","O"),AND(J7=$O$2,J7-I7>0),$K$2,AND(J6=$O$2,J6-I6>0),$K$2,J6-I6>0,"D",J6-I6<1,"O") | L5: =IFS(ISBLANK(K6),,AND(K6>=$O$2,K7>=$O$2),IF(K6-J6>0,"D","O"),AND(K7=$O$2,K7-J7>0),$K$2,AND(K6=$O$2,K6-J6>0),$K$2,K6-J6>0,"D",K6-J6<1,"O") | M5: =IFS(ISBLANK(L6),,AND(L6>=$O$2,L7>=$O$2),IF(L6-K6>0,"D","O"),AND(L7=$O$2,L7-K7>0),$K$2,AND(L6=$O$2,L6-K6>0),$K$2,L6-K6>0,"D",L6-K6<1,"O") | ... AD5: =IFS(ISBLANK(AC6),,AND(AC6>=$O$2,AC7>=$O$2),IF(AC6-AB6>0,"D","O"),AND(AC7=$O$2,AC7-AB7>0),$K$2,AND(AC6=$O$2,AC6-AB6>0),$K$2,AC6-AB6>0,"D",AC6-AB6<1,"O")
C6: Score Us | D6: =IF(ISBLANK(D40),IF(ISBLANK(D43), ,0),1) | E6: =IF(ISBLANK(E40),IF(ISBLANK(E43), ,D6),D6+1) | F6: =IF(ISBLANK(F40),IF(ISBLANK(F43), ,E6),E6+1) | G6: =IF(ISBLANK(G40),IF(ISBLANK(G43), ,F6),F6+1) | H6: =IF(ISBLANK(H40),IF(ISBLANK(H43), ,G6),G6+1) | I6: =IF(ISBLANK(I40),IF(ISBLANK(I43), ,H6),H6+1) | J6: =IF(ISBLANK(J40),IF(ISBLANK(J43), ,I6),I6+1) | K6: =IF(ISBLANK(K40),IF(ISBLANK(K43), ,J6),J6+1) | L6: =IF(ISBLANK(L40),IF(ISBLANK(L43), ,K6),K6+1) | ... AD6: =IF(ISBLANK(AD40),IF(ISBLANK(AD43), ,AC6),AC6+1) | AE6: Active? | AF6: Count | AG6: O Count | AH6: D Count | AI6: O Rating | AJ6: D Rating
C7: Score Them | D7: =IF(ISBLANK(D43),IF(ISBLANK(D40), ,0),1) | E7: =IF(ISBLANK(E43),IF(ISBLANK(E40), ,D7),D7+1) | F7: =IF(ISBLANK(F43),IF(ISBLANK(F40), ,E7),E7+1) | G7: =IF(ISBLANK(G43),IF(ISBLANK(G40), ,F7),F7+1) | H7: =IF(ISBLANK(H43),IF(ISBLANK(H40), ,G7),G7+1) | I7: =IF(ISBLANK(I43),IF(ISBLANK(I40), ,H7),H7+1) | J7: =IF(ISBLANK(J43),IF(ISBLANK(J40), ,I7),I7+1) | K7: =IF(ISBLANK(K43),IF(ISBLANK(K40), ,J7),J7+1) | L7: =IF(ISBLANK(L43),IF(ISBLANK(L40), ,K7),K7+1) | ... AD7: =IF(ISBLANK(AD43),IF(ISBLANK(AD40), ,AC7),AC7+1)
A8: Running | B8: Prev Pts | C8: Name
A9: =AF9+B9 -> 0 | B9: ='G1'!AF9 -> 0 | C9: =Tourn_Summary!C4 -> MMP 1 | AF9: =SUM(D9:AD9) -> 0 | AG9: =SUMIF($D$5:$AD$5,"=O",D9:AD9) -> 0 | AH9: =SUMIF($D$5:$AD$5,"=D",D9:AD9) -> 0 | AI9: =SUMPRODUCT(D9:AD9,$D$45:$AD$45) -> 0 | AJ9: =SUMPRODUCT(D9:AD9,$D$46:$AD$46) -> 0
A10: =AF10+B10 -> 0 | B10: ='G1'!AF10 -> 0 | C10: =Tourn_Summary!C5 -> MMP 2 | AF10: =SUM(D10:AD10) -> 0 | AG10: =SUMIF($D$5:$AD$5,"=O",D10:AD10) -> 0 | AH10: =SUMIF($D$5:$AD$5,"=D",D10:AD10) -> 0 | AI10: =SUMPRODUCT(D10:AD10,$D$45:$AD$45) -> 0 | AJ10: =SUMPRODUCT(D10:AD10,$D$46:$AD$46) -> 0
A11: =AF11+B11 -> 0 | B11: ='G1'!AF11 -> 0 | C11: =Tourn_Summary!C6 -> MMP 3 | AF11: =SUM(D11:AD11) -> 0 | AG11: =SUMIF($D$5:$AD$5,"=O",D11:AD11) -> 0 | AH11: =SUMIF($D$5:$AD$5,"=D",D11:AD11) -> 0 | AI11: =SUMPRODUCT(D11:AD11,$D$45:$AD$45) -> 0 | AJ11: =SUMPRODUCT(D11:AD11,$D$46:$AD$46) -> 0
A12: =AF12+B12 -> 0 | B12: ='G1'!AF12 -> 0 | C12: =Tourn_Summary!C7 -> MMP 4 | AF12: =SUM(D12:AD12) -> 0 | AG12: =SUMIF($D$5:$AD$5,"=O",D12:AD12) -> 0 | AH12: =SUMIF($D$5:$AD$5,"=D",D12:AD12) -> 0 | AI12: =SUMPRODUCT(D12:AD12,$D$45:$AD$45) -> 0 | AJ12: =SUMPRODUCT(D12:AD12,$D$46:$AD$46) -> 0
A13: =AF13+B13 -> 0 | B13: ='G1'!AF13 -> 0 | C13: =Tourn_Summary!C8 -> MMP 5 | AF13: =SUM(D13:AD13) -> 0 | AG13: =SUMIF($D$5:$AD$5,"=O",D13:AD13) -> 0 | AH13: =SUMIF($D$5:$AD$5,"=D",D13:AD13) -> 0 | AI13: =SUMPRODUCT(D13:AD13,$D$45:$AD$45) -> 0 | AJ13: =SUMPRODUCT(D13:AD13,$D$46:$AD$46) -> 0
A14: =AF14+B14 -> 0 | B14: ='G1'!AF14 -> 0 | C14: =Tourn_Summary!C9 -> MMP 6 | AF14: =SUM(D14:AD14) -> 0 | AG14: =SUMIF($D$5:$AD$5,"=O",D14:AD14) -> 0 | AH14: =SUMIF($D$5:$AD$5,"=D",D14:AD14) -> 0 | AI14: =SUMPRODUCT(D14:AD14,$D$45:$AD$45) -> 0 | AJ14: =SUMPRODUCT(D14:AD14,$D$46:$AD$46) -> 0
A15: =AF15+B15 -> 0 | B15: ='G1'!AF15 -> 0 | C15: =Tourn_Summary!C10 -> MMP 7 | AF15: =SUM(D15:AD15) -> 0 | AG15: =SUMIF($D$5:$AD$5,"=O",D15:AD15) -> 0 | AH15: =SUMIF($D$5:$AD$5,"=D",D15:AD15) -> 0 | AI15: =SUMPRODUCT(D15:AD15,$D$45:$AD$45) -> 0 | AJ15: =SUMPRODUCT(D15:AD15,$D$46:$AD$46) -> 0
A16: =AF16+B16 -> 0 | B16: ='G1'!AF16 -> 0 | C16: =Tourn_Summary!C11 -> MMP 8 | AF16: =SUM(D16:AD16) -> 0 | AG16: =SUMIF($D$5:$AD$5,"=O",D16:AD16) -> 0 | AH16: =SUMIF($D$5:$AD$5,"=D",D16:AD16) -> 0 | AI16: =SUMPRODUCT(D16:AD16,$D$45:$AD$45) -> 0 | AJ16: =SUMPRODUCT(D16:AD16,$D$46:$AD$46) -> 0
A17: =AF17+B17 -> 0 | B17: ='G1'!AF17 -> 0 | C17: =Tourn_Summary!C12 -> MMP 9 | AF17: =SUM(D17:AD17) -> 0 | AG17: =SUMIF($D$5:$AD$5,"=O",D17:AD17) -> 0 | AH17: =SUMIF($D$5:$AD$5,"=D",D17:AD17) -> 0 | AI17: =SUMPRODUCT(D17:AD17,$D$45:$AD$45) -> 0 | AJ17: =SUMPRODUCT(D17:AD17,$D$46:$AD$46) -> 0
A18: =AF18+B18 -> 0 | B18: ='G1'!AF18 -> 0 | C18: =Tourn_Summary!C13 -> MMP 10 | AF18: =SUM(D18:AD18) -> 0 | AG18: =SUMIF($D$5:$AD$5,"=O",D18:AD18) -> 0 | AH18: =SUMIF($D$5:$AD$5,"=D",D18:AD18) -> 0 | AI18: =SUMPRODUCT(D18:AD18,$D$45:$AD$45) -> 0 | AJ18: =SUMPRODUCT(D18:AD18,$D$46:$AD$46) -> 0
A19: =AF19+B19 -> 0 | B19: ='G1'!AF19 -> 0 | C19: =Tourn_Summary!C14 -> MMP 11 | AF19: =SUM(D19:AD19) -> 0 | AG19: =SUMIF($D$5:$AD$5,"=O",D19:AD19) -> 0 | AH19: =SUMIF($D$5:$AD$5,"=D",D19:AD19) -> 0 | AI19: =SUMPRODUCT(D19:AD19,$D$45:$AD$45) -> 0 | AJ19: =SUMPRODUCT(D19:AD19,$D$46:$AD$46) -> 0
